Workbook
Name div.yield: #REF!
Name expiry: #REF!
Name OptionPayout: _xlfn.LAMBDA(_xlpm.type,_xlpm.spot,_xlpm.strike,MAX(0,(_xlpm.spot-_xlpm.strike)*IF(_xlpm.type="Call",1,-1)))
Name PlusIt: _xlfn.LAMBDA(_xlpm.ksu,_xlpm.zips,_xlpm.ksu+_xlpm.zips)
Name riskfree: #REF!
Name spot: #REF!
Name strike: #REF!
Name TimesIt: _xlfn.LAMBDA(_xlpm.first,_xlpm.second,_xlpm.first*_xlpm.second)
Name vol: #REF!

Sheet Parameters 1
B2: Standard Inputs - Base Scenario
B3: Start Date | C3: 45292 | E3: End Date | F3: 45657
B4: Domestic (London) Risk-Free Rate | C4: 0.05 | E4: Domestic Risk-Free Rate | F4: =C4/12 -> 0.0041666667
B5: Foreign (U.S.) Risk-Free Rate | C5: 0.045 | E5: Foreign Risk-Free Rate | F5: =C5/12 -> 0.00375
B6: Foreign Investment | C6: #VALUE!
B9: Historical Foreign Investment Returns (NYSE:AAPL) | H9: Monthly Historical Foreign Investment Returns (NYSE:AAPL)
B10: Date | C10: Price | E10: Δ (Delta) | F10: Return | H10: Month | I10: EOM Price | J10: Return
B11: {=_xlfn.STOCKHISTORY(C6,C3,F3,0,0,0,1)} -> 45293 | C11: 185.64 | H11: January | I11: =C31 -> 184.4 | J11: =I11/C11-1 -> -0.0066795949
B12: 45294 | C12: 184.25 | E12: =C12/C11-1 -> -0.0074876104 | F12: =C12/$C$11-1 -> -0.0074876104 | H12: February | I12: =C51 -> 180.75 | J12: =I12/I11-1 -> -0.019793926
B13: 45295 | C13: 181.91 | E13: =C13/C12-1 -> -0.012700136 | F13: =C13/$C$11-1 -> -0.020092652 | H13: March | I13: =C71 -> 171.48 | J13: =I13/I12-1 -> -0.051286307
B14: 45296 | C14: 181.18 | E14: =C14/C13-1 -> -0.0040129734 | F14: =C14/$C$11-1 -> -0.024024995 | H14: April | I14: =C93 -> 170.33 | J14: =I14/I13-1 -> -0.0067063214
B15: 45299 | C15: 185.56 | E15: =C15/C14-1 -> 0.024174854 | F15: =C15/$C$11-1 -> -0.00043094161 | H15: May | I15: =C115 -> 192.25 | J15: =I15/I14-1 -> 0.12869136
B16: 45300 | C16: 185.14 | E16: =C16/C15-1 -> -0.0022634188 | F16: =C16/$C$11-1 -> -0.002693385 | H16: June | I16: =C134 -> 210.62 | J16: =I16/I15-1 -> 0.095552666
B17: 45301 | C17: 186.19 | E17: =C17/C16-1 -> 0.0056713838 | F17: =C17/$C$11-1 -> 0.0029627236 | H17: July | I17: =C156 -> 222.08 | J17: =I17/I16-1 -> 0.054410787
B18: 45302 | C18: 185.59 | E18: =C18/C17-1 -> -0.0032225146 | F18: =C18/$C$11-1 -> -0.0002693385 | H18: August | I18: =C178 -> 229 | J18: =I18/I17-1 -> 0.031159942
B19: 45303 | C19: 185.92 | E19: =C19/C18-1 -> 0.001778113 | F19: =C19/$C$11-1 -> 0.0015082956 | H19: September | I19: =C198 -> 233 | J19: =I19/I18-1 -> 0.017467249
B20: 45307 | C20: 183.63 | E20: =C20/C19-1 -> -0.012317126 | F20: =C20/$C$11-1 -> -0.010827408 | H20: October | I20: =C221 -> 225.91 | J20: =I20/I19-1 -> -0.030429185
B21: 45308 | C21: 182.68 | E21: =C21/C20-1 -> -0.0051734466 | F21: =C21/$C$11-1 -> -0.015944839 | H21: November | I21: =C241 -> 237.33 | J21: =I21/I20-1 -> 0.050551104
B22: 45309 | C22: 188.63 | E22: =C22/C21-1 -> 0.032570615 | F22: =C22/$C$11-1 -> 0.016106443 | H22: December | I22: =C262 -> 250.42 | J22: =I22/I21-1 -> 0.055155269
B23: 45310 | C23: 191.56 | E23: =C23/C22-1 -> 0.015533054 | F23: =C23/$C$11-1 -> 0.031889679
B24: 45313 | C24: 193.89 | E24: =C24/C23-1 -> 0.012163291 | F24: =C24/$C$11-1 -> 0.044440853 | H24: Monthly Spot Rate
B25: 45314 | C25: 195.18 | E25: =C25/C24-1 -> 0.006653257 | F25: =C25/$C$11-1 -> 0.051389787 | H25: Month | I25: Exchange Rate (USD/EUR)
B26: 45315 | C26: 194.5 | E26: =C26/C25-1 -> -0.0034839635 | F26: =C26/$C$11-1 -> 0.047726783 | H26: December 2023 | I26: 1.0893
B27: 45316 | C27: 194.17 | E27: =C27/C26-1 -> -0.0016966581 | F27: =C27/$C$11-1 -> 0.045949149 | H27: January | I27: 1.1035
B28: 45317 | C28: 192.42 | E28: =C28/C27-1 -> -0.0090127208 | F28: =C28/$C$11-1 -> 0.036522301 | H28: February | I28: 1.0875
B29: 45320 | C29: 191.73 | E29: =C29/C28-1 -> -0.0035859058 | F29: =C29/$C$11-1 -> 0.03280543 | H29: March | I29: 1.0846
B30: 45321 | C30: 188.04 | E30: =C30/C29-1 -> -0.019245814 | F30: =C30/$C$11-1 -> 0.012928248 | H30: April | I30: 1.074
B31: 45322 | C31: 184.4 | E31: =C31/C30-1 -> -0.019357583 | F31: =C31/$C$11-1 -> -0.0066795949 | H31: May | I31: 1.0716
B32: 45323 | C32: 186.86 | E32: =C32/C31-1 -> 0.013340564 | F32: =C32/$C$11-1 -> 0.0065718595 | H32: June | I32: 1.0857
B33: 45324 | C33: 185.85 | E33: =C33/C32-1 -> -0.0054051161 | F33: =C33/$C$11-1 -> 0.0011312217 | H33: July | I33: 1.0737
B34: 45327 | C34: 187.68 | E34: =C34/C33-1 -> 0.0098466505 | F34: =C34/$C$11-1 -> 0.010989011 | H34: August | I34: 1.0789
B35: 45328 | C35: 189.3 | E35: =C35/C34-1 -> 0.0086317136 | F35: =C35/$C$11-1 -> 0.019715579 | H35: September | I35: 1.1049
B36: 45329 | C36: 189.41 | E36: =C36/C35-1 -> 0.00058108822 | F36: =C36/$C$11-1 -> 0.020308123 | H36: October | I36: 1.1068
B37: 45330 | C37: 188.32 | E37: =C37/C36-1 -> -0.005754712 | F37: =C37/$C$11-1 -> 0.014436544 | H37: November | I37: 1.087
... B39: 45334 | C39: 187.15 | E39: =C39/C38-1 -> -0.0090018533 | F39: =C39/$C$11-1 -> 0.0081340228 | H39: January 2025 | I39: 1.035
B40: 45335 | C40: 185.04 | E40: =C40/C39-1 -> -0.011274379 | F40: =C40/$C$11-1 -> -0.0032320621
B41: 45336 | C41: 184.15 | E41: =C41/C40-1 -> -0.0048097709 | F41: =C41/$C$11-1 -> -0.0080262874
B42: 45337 | C42: 183.86 | E42: =C42/C41-1 -> -0.0015748031 | F42: =C42/$C$11-1 -> -0.0095884508
B43: 45338 | C43: 182.31 | E43: =C43/C42-1 -> -0.0084303274 | F43: =C43/$C$11-1 -> -0.017937944
B44: 45342 | C44: 181.56 | E44: =C44/C43-1 -> -0.004113872 | F44: =C44/$C$11-1 -> -0.021978022
...

Sheet Hedged vs Unhedged Returns
B2: Simulated Month to Month Returns - Unhedged
H3: 100
B4: Month | C4: Foreign Asset Return | D4: Spot Exchange Rate (t) | E4: Spot Exchange Rate (t-1) | F4: Spot Exchange Return | G4: Unhedged Return | H4: Unhedged Index | I4: Deviation
B5: {=_xlfn.SEQUENCE(12,1,1/1/2024,32)} -> 0.00049407115 | C5: {='Parameters 1'!J11:J22} -> -0.0066795949 | D5: {='Parameters 1'!I27:I38} -> 1.1035 | E5: {='Parameters 1'!I26:I37} -> 1.0893 | F5: {=_xlfn.ANCHORARRAY(E5)/_xlfn.ANCHORARRAY(D5)-1} -> -0.012868147 | G5: {=(1+_xlfn.ANCHORARRAY(C5))*(1+_xlfn.ANCHORARRAY(F5))-1} -> -0.019461788 | H5: =H3*(1+G5) -> 98.053821 | I5: =_xlfn.STDEV.S(H5:H16)/100 -> 0.15428181
B6: 32.000494 | C6: -0.019793926 | D6: 1.0875 | E6: 1.1035 | F6: 0.014712644 | G6: -0.0053725036 | H6: =H5*(1+G6) -> 97.527027
B7: 64.000494 | C7: -0.051286307 | D7: 1.0846 | E7: 1.0875 | F7: 0.0026737968 | G7: -0.048749639 | H7: =H6*(1+G7) -> 92.772619
B8: 96.000494 | C8: -0.0067063214 | D8: 1.074 | E8: 1.0846 | F8: 0.0098696462 | G8: 0.0030971357 | H8: =H7*(1+G8) -> 93.059949
B9: 128.00049 | C9: 0.12869136 | D9: 1.0716 | E9: 1.074 | F9: 0.0022396417 | G9: 0.13121923 | H9: =H8*(1+G9) -> 105.2712
B10: 160.00049 | C10: 0.095552666 | D10: 1.0857 | E10: 1.0716 | F10: -0.012987013 | G10: 0.081324709 | H10: =H9*(1+G10) -> 113.83235
B11: 192.00049 | C11: 0.054410787 | D11: 1.0737 | E11: 1.0857 | F11: 0.011176306 | G11: 0.066195205 | H11: =H10*(1+G11) -> 121.36751
B12: 224.00049 | C12: 0.031159942 | D12: 1.0789 | E12: 1.0737 | F12: -0.0048197238 | G12: 0.026190036 | H12: =H11*(1+G12) -> 124.54613
B13: 256.00049 | C13: 0.017467249 | D13: 1.1049 | E13: 1.0789 | F13: -0.023531541 | G13: -0.0064753237 | H13: =H12*(1+G13) -> 123.73965
B14: 288.00049 | C14: -0.030429185 | D14: 1.1068 | E14: 1.1049 | F14: -0.0017166606 | G14: -0.032093609 | H14: =H13*(1+G14) -> 119.7684
B15: 320.00049 | C15: 0.050551104 | D15: 1.087 | E15: 1.1068 | F15: 0.018215271 | G15: 0.069687178 | H15: =H14*(1+G15) -> 128.11472
B16: 352.00049 | C16: 0.055155269 | D16: 1.0543 | E16: 1.087 | F16: 0.03101584 | G16: 0.087881796 | H16: =H15*(1+G16) -> 139.37367
B19: Simulated Month to Month Returns - Hedged
B20: Month | C20: Foreign Asset Return | D20: Spot Exchange Rate (t) | E20: Spot Exchange Rate (t-1) | F20: Spot Exchange Return | G20: Risk Free Domestic | H20: Risk Free Foreign | I20: Forward Price | J20: Hedged Return | K20: Hedged Index | L20: Deviation
B21: {=_xlfn.SEQUENCE(12,1,1/1/2024,32)} -> 0.00049407115 | C21: {='Parameters 1'!J11:J22} -> -0.0066795949 | D21: {='Parameters 1'!I27:I38} -> 1.1035 | E21: {='Parameters 1'!I26:I37} -> 1.0893 | F21: {=_xlfn.ANCHORARRAY(D21)/_xlfn.ANCHORARRAY(E21)-1} -> 0.013035895 | G21: ='Parameters 1'!$F$4 -> 0.0041666667 | H21: ='Parameters 1'!$F$5 -> 0.00375 | I21: =E21*(1+G21)/(1+H21) -> 1.0897522 | J21: =(I21/E21)*(1+C21)-1 -> -0.0062672577 | K21: =H3*(1+J21) -> 99.373274 | L21: =_xlfn.STDEV.S(K21:K32)/100 -> 0.15207641
B22: 32.000494 | C22: -0.019793926 | D22: 1.0875 | E22: 1.1035 | F22: -0.01449932 | G22: ='Parameters 1'!$F$4 -> 0.0041666667 | H22: ='Parameters 1'!$F$5 -> 0.00375 | I22: =E22*(1+G22)/(1+H22) -> 1.1039581 | J22: =(I22/E22)*(1+C22)-1 -> -0.019387033 | K22: =K21*(1+J22) -> 97.446721
B23: 64.000494 | C23: -0.051286307 | D23: 1.0846 | E23: 1.0875 | F23: -0.0026666667 | G23: ='Parameters 1'!$F$4 -> 0.0041666667 | H23: ='Parameters 1'!$F$5 -> 0.00375 | I23: =E23*(1+G23)/(1+H23) -> 1.0879514 | J23: =(I23/E23)*(1+C23)-1 -> -0.050892487 | K23: =K22*(1+J23) -> 92.487415
B24: 96.000494 | C24: -0.0067063214 | D24: 1.074 | E24: 1.0846 | F24: -0.0097731883 | G24: ='Parameters 1'!$F$4 -> 0.0041666667 | H24: ='Parameters 1'!$F$5 -> 0.00375 | I24: =E24*(1+G24)/(1+H24) -> 1.0850502 | J24: =(I24/E24)*(1+C24)-1 -> -0.0062939953 | K24: =K23*(1+J24) -> 91.9053
B25: 128.00049 | C25: 0.12869136 | D25: 1.0716 | E25: 1.074 | F25: -0.0022346369 | G25: ='Parameters 1'!$F$4 -> 0.0041666667 | H25: ='Parameters 1'!$F$5 -> 0.00375 | I25: =E25*(1+G25)/(1+H25) -> 1.0744458 | J25: =(I25/E25)*(1+C25)-1 -> 0.12915989 | K25: =K24*(1+J25) -> 103.77578
B26: 160.00049 | C26: 0.095552666 | D26: 1.0857 | E26: 1.0716 | F26: 0.013157895 | G26: ='Parameters 1'!$F$4 -> 0.0041666667 | H26: ='Parameters 1'!$F$5 -> 0.00375 | I26: =E26*(1+G26)/(1+H26) -> 1.0720448 | J26: =(I26/E26)*(1+C26)-1 -> 0.096007441 | K26: =K25*(1+J26) -> 113.73903
B27: 192.00049 | C27: 0.054410787 | D27: 1.0737 | E27: 1.0857 | F27: -0.011052777 | G27: ='Parameters 1'!$F$4 -> 0.0041666667 | H27: ='Parameters 1'!$F$5 -> 0.00375 | I27: =E27*(1+G27)/(1+H27) -> 1.0861507 | J27: =(I27/E27)*(1+C27)-1 -> 0.054848484 | K27: =K26*(1+J27) -> 119.97744
B28: 224.00049 | C28: 0.031159942 | D28: 1.0789 | E28: 1.0737 | F28: 0.004843066 | G28: ='Parameters 1'!$F$4 -> 0.0041666667 | H28: ='Parameters 1'!$F$5 -> 0.00375 | I28: =E28*(1+G28)/(1+H28) -> 1.0741457 | J28: =(I28/E28)*(1+C28)-1 -> 0.031587987 | K28: =K27*(1+J28) -> 123.76728
B29: 256.00049 | C29: 0.017467249 | D29: 1.1049 | E29: 1.0789 | F29: 0.024098619 | G29: ='Parameters 1'!$F$4 -> 0.0041666667 | H29: ='Parameters 1'!$F$5 -> 0.00375 | I29: =E29*(1+G29)/(1+H29) -> 1.0793479 | J29: =(I29/E29)*(1+C29)-1 -> 0.01788961 | K29: =K28*(1+J29) -> 125.98143
B30: 288.00049 | C30: -0.030429185 | D30: 1.1068 | E30: 1.1049 | F30: 0.0017196126 | G30: ='Parameters 1'!$F$4 -> 0.0041666667 | H30: ='Parameters 1'!$F$5 -> 0.00375 | I30: =E30*(1+G30)/(1+H30) -> 1.1053587 | J30: =(I30/E30)*(1+C30)-1 -> -0.030026706 | K30: =K29*(1+J30) -> 122.19863
B31: 320.00049 | C31: 0.050551104 | D31: 1.087 | E31: 1.1068 | F31: -0.017889411 | G31: ='Parameters 1'!$F$4 -> 0.0041666667 | H31: ='Parameters 1'!$F$5 -> 0.00375 | I31: =E31*(1+G31)/(1+H31) -> 1.1072594 | J31: =(I31/E31)*(1+C31)-1 -> 0.050987199 | K31: =K30*(1+J31) -> 128.42919
B32: 352.00049 | C32: 0.055155269 | D32: 1.0543 | E32: 1.087 | F32: -0.030082797 | G32: ='Parameters 1'!$F$4 -> 0.0041666667 | H32: ='Parameters 1'!$F$5 -> 0.00375 | I32: =E32*(1+G32)/(1+H32) -> 1.0874512 | J32: =(I32/E32)*(1+C32)-1 -> 0.055593275 | K32: =K31*(1+J32) -> 135.56899

Sheet PNL 1
B2: PNL 1 | J2: Index | N2: Row Labels | O2: Sum of Unhedged Index | P2: Sum of Hedged Index
B3: Month | G3: Hedged | H3: Unhedged | J3: Month | K3: Unhedged Index | L3: Hedged Index | N3: 0.00049768519 | O3: 98.053821 | P3: 99.373274
C4: {=+'Parameters 1'!H11:H22} -> January | G4: {=+'Hedged vs Unhedged Returns'!J21:J32} -> -0.0062672577 | H4: {=_xlfn.ANCHORARRAY('Hedged vs Unhedged Returns'!G5)} -> -0.019461788 | J4: {=+_xlfn.SEQUENCE(12,1,1/1/2024,31)} -> 0.00049407115 | K4: 98.053821 | L4: 99.373274 | N4: 31.000498 | O4: 97.527027 | P4: 97.446721
C5: February | G5: -0.019387033 | H5: -0.0053725036 | J5: 31.000494 | K5: 97.527027 | L5: 97.446721 | N5: 62.000498 | O5: 92.772619 | P5: 92.487415
C6: March | G6: -0.050892487 | H6: -0.048749639 | J6: 62.000494 | K6: 92.772619 | L6: 92.487415 | N6: 93.000498 | O6: 93.059949 | P6: 91.9053
C7: April | G7: -0.0062939953 | H7: 0.0030971357 | J7: 93.000494 | K7: 93.059949 | L7: 91.9053 | N7: 124.0005 | O7: 105.2712 | P7: 103.77578
C8: May | G8: 0.12915989 | H8: 0.13121923 | J8: 124.00049 | K8: 105.2712 | L8: 103.77578 | N8: 155.0005 | O8: 113.83235 | P8: 113.73903
C9: June | G9: 0.096007441 | H9: 0.081324709 | J9: 155.00049 | K9: 113.83235 | L9: 113.73903 | N9: 186.0005 | O9: 121.36751 | P9: 119.97744
C10: July | G10: 0.054848484 | H10: 0.066195205 | J10: 186.00049 | K10: 121.36751 | L10: 119.97744 | N10: 217.0005 | O10: 124.54613 | P10: 123.76728
C11: August | G11: 0.031587987 | H11: 0.026190036 | J11: 217.00049 | K11: 124.54613 | L11: 123.76728 | N11: 248.0005 | O11: 123.73965 | P11: 125.98143
C12: September | G12: 0.01788961 | H12: -0.0064753237 | J12: 248.00049 | K12: 123.73965 | L12: 125.98143 | N12: 279.0005 | O12: 119.7684 | P12: 122.19863
C13: October | G13: -0.030026706 | H13: -0.032093609 | J13: 279.00049 | K13: 119.7684 | L13: 122.19863 | N13: 310.0005 | O13: 128.11472 | P13: 128.42919
C14: November | G14: 0.050987199 | H14: 0.069687178 | J14: 310.00049 | K14: 128.11472 | L14: 128.42919 | N14: 341.0005 | O14: 139.37367 | P14: 135.56899
C15: December | G15: 0.055593275 | H15: 0.087881796 | J15: 341.00049 | K15: 139.37367 | L15: 135.56899 | N15: Grand Total | O15: 1357.4271 | P15: 1354.6505
B16: Cumulative | G16: =('Hedged vs Unhedged Returns'!K32-100)/100 -> 0.35568991 | H16: =('Hedged vs Unhedged Returns'!H16-100)/100 -> 0.39373674

Sheet Parameters 2
B2: Standard Inputs - Scenario 2
B3: Start Date | C3: 45292 | E3: End Date | F3: 45657
B4: Domestic (London) Risk-Free Rate | C4: 0.05 | E4: Domestic Risk-Free Rate | F4: =C4/12 -> 0.0041666667
B5: Foreign (Argentina) Risk-Free Rate | C5: 0.32 | E5: Foreign Risk-Free Rate | F5: =C5/12 -> 0.026666667
B6: Foreign Investment | C6: #VALUE! | E6: <- traded on the Buenos Aires Stock Exchange
B9: Historical Foreign Investment Returns (NYSE:AAPL) | H9: Monthly Historical Foreign Investment Returns (NYSE:AAPL)
B10: Date | C10: Price | E10: Δ (Delta) | F10: Return | H10: Month | I10: EOM Price | J10: Return
B11: {=_xlfn.STOCKHISTORY(C6,C3,F3,0,0,0,1)} -> 45293 | C11: 185.64 | H11: January | I11: =C31 -> 184.4 | J11: =I11/C11-1 -> -0.0066795949
B12: 45294 | C12: 184.25 | E12: =C12/C11-1 -> -0.0074876104 | F12: =C12/$C$11-1 -> -0.0074876104 | H12: February | I12: =C51 -> 180.75 | J12: =I12/I11-1 -> -0.019793926
B13: 45295 | C13: 181.91 | E13: =C13/C12-1 -> -0.012700136 | F13: =C13/$C$11-1 -> -0.020092652 | H13: March | I13: =C71 -> 171.48 | J13: =I13/I12-1 -> -0.051286307
B14: 45296 | C14: 181.18 | E14: =C14/C13-1 -> -0.0040129734 | F14: =C14/$C$11-1 -> -0.024024995 | H14: April | I14: =C93 -> 170.33 | J14: =I14/I13-1 -> -0.0067063214
B15: 45299 | C15: 185.56 | E15: =C15/C14-1 -> 0.024174854 | F15: =C15/$C$11-1 -> -0.00043094161 | H15: May | I15: =C115 -> 192.25 | J15: =I15/I14-1 -> 0.12869136
B16: 45300 | C16: 185.14 | E16: =C16/C15-1 -> -0.0022634188 | F16: =C16/$C$11-1 -> -0.002693385 | H16: June | I16: =C134 -> 210.62 | J16: =I16/I15-1 -> 0.095552666
B17: 45301 | C17: 186.19 | E17: =C17/C16-1 -> 0.0056713838 | F17: =C17/$C$11-1 -> 0.0029627236 | H17: July | I17: =C156 -> 222.08 | J17: =I17/I16-1 -> 0.054410787
B18: 45302 | C18: 185.59 | E18: =C18/C17-1 -> -0.0032225146 | F18: =C18/$C$11-1 -> -0.0002693385 | H18: August | I18: =C178 -> 229 | J18: =I18/I17-1 -> 0.031159942
B19: 45303 | C19: 185.92 | E19: =C19/C18-1 -> 0.001778113 | F19: =C19/$C$11-1 -> 0.0015082956 | H19: September | I19: =C198 -> 233 | J19: =I19/I18-1 -> 0.017467249
B20: 45307 | C20: 183.63 | E20: =C20/C19-1 -> -0.012317126 | F20: =C20/$C$11-1 -> -0.010827408 | H20: October | I20: =C221 -> 225.91 | J20: =I20/I19-1 -> -0.030429185
B21: 45308 | C21: 182.68 | E21: =C21/C20-1 -> -0.0051734466 | F21: =C21/$C$11-1 -> -0.015944839 | H21: November | I21: =C241 -> 237.33 | J21: =I21/I20-1 -> 0.050551104
B22: 45309 | C22: 188.63 | E22: =C22/C21-1 -> 0.032570615 | F22: =C22/$C$11-1 -> 0.016106443 | H22: December | I22: =C262 -> 250.42 | J22: =I22/I21-1 -> 0.055155269
B23: 45310 | C23: 191.56 | E23: =C23/C22-1 -> 0.015533054 | F23: =C23/$C$11-1 -> 0.031889679
B24: 45313 | C24: 193.89 | E24: =C24/C23-1 -> 0.012163291 | F24: =C24/$C$11-1 -> 0.044440853 | H24: Monthly Spot Rate
B25: 45314 | C25: 195.18 | E25: =C25/C24-1 -> 0.006653257 | F25: =C25/$C$11-1 -> 0.051389787 | H25: Month | I25: Exchange Rate (Argentinian Pesos per 1 EUR)
B26: 45315 | C26: 194.5 | E26: =C26/C25-1 -> -0.0034839635 | F26: =C26/$C$11-1 -> 0.047726783 | H26: December 2023 | I26: 675.36
B27: 45316 | C27: 194.17 | E27: =C27/C26-1 -> -0.0016966581 | F27: =C27/$C$11-1 -> 0.045949149 | H27: January | I27: 892.06
B28: 45317 | C28: 192.42 | E28: =C28/C27-1 -> -0.0090127208 | F28: =C28/$C$11-1 -> 0.036522301 | H28: February | I28: 900.09
B29: 45320 | C29: 191.73 | E29: =C29/C28-1 -> -0.0035859058 | F29: =C29/$C$11-1 -> 0.03280543 | H29: March | I29: 924.21
B30: 45321 | C30: 188.04 | E30: =C30/C29-1 -> -0.019245814 | F30: =C30/$C$11-1 -> 0.012928248 | H30: April | I30: 930.23
B31: 45322 | C31: 184.4 | E31: =C31/C30-1 -> -0.019357583 | F31: =C31/$C$11-1 -> -0.0066795949 | H31: May | I31: 956.02
B32: 45323 | C32: 186.86 | E32: =C32/C31-1 -> 0.013340564 | F32: =C32/$C$11-1 -> 0.0065718595 | H32: June | I32: 971.82
B33: 45324 | C33: 185.85 | E33: =C33/C32-1 -> -0.0054051161 | F33: =C33/$C$11-1 -> 0.0011312217 | H33: July | I33: 1000
B34: 45327 | C34: 187.68 | E34: =C34/C33-1 -> 0.0098466505 | F34: =C34/$C$11-1 -> 0.010989011 | H34: August | I34: 1035.2
B35: 45328 | C35: 189.3 | E35: =C35/C34-1 -> 0.0086317136 | F35: =C35/$C$11-1 -> 0.019715579 | H35: September | I35: 1066.1
B36: 45329 | C36: 189.41 | E36: =C36/C35-1 -> 0.00058108822 | F36: =C36/$C$11-1 -> 0.020308123 | H36: October | I36: 1067.24
B37: 45330 | C37: 188.32 | E37: =C37/C36-1 -> -0.005754712 | F37: =C37/$C$11-1 -> 0.014436544 | H37: November | I37: 1062.7
... B39: 45334 | C39: 187.15 | E39: =C39/C38-1 -> -0.0090018533 | F39: =C39/$C$11-1 -> 0.0081340228 | H39: January 2025 | I39: 1076.65
B40: 45335 | C40: 185.04 | E40: =C40/C39-1 -> -0.011274379 | F40: =C40/$C$11-1 -> -0.0032320621
B41: 45336 | C41: 184.15 | E41: =C41/C40-1 -> -0.0048097709 | F41: =C41/$C$11-1 -> -0.0080262874
B42: 45337 | C42: 183.86 | E42: =C42/C41-1 -> -0.0015748031 | F42: =C42/$C$11-1 -> -0.0095884508
B43: 45338 | C43: 182.31 | E43: =C43/C42-1 -> -0.0084303274 | F43: =C43/$C$11-1 -> -0.017937944
B44: 45342 | C44: 181.56 | E44: =C44/C43-1 -> -0.004113872 | F44: =C44/$C$11-1 -> -0.021978022
...

Sheet Currency Variance Scenario
B3: Simulated Month to Month Returns - Unhedged
H4: 100
B5: Month | C5: Foreign Asset Return | D5: Spot Exchange Rate (t) | E5: Spot Exchange Rate (t-1) | F5: Spot Exchange Return | G5: Unhedged Return | H5: Unhedged Index | I5: Deviation
B6: {=_xlfn.SEQUENCE(12,1,1/1/2024,32)} -> 0.00049407115 | C6: {='Parameters 1'!J11:J22} -> -0.0066795949 | D6: ='Parameters 2'!I27 -> 892.06 | E6: ='Parameters 2'!I26 -> 675.36 | F6: {=E6:E17/D6:D17-1} -> -0.24292088 | G6: {=(1+_xlfn.ANCHORARRAY(C6))*(1+_xlfn.ANCHORARRAY(F6))-1} -> -0.24797786 | H6: =H4*(1+G6) -> 75.202214 | I6: =_xlfn.STDEV.S(H6:H17)/100 -> 0.056564792
B7: 32.000494 | C7: -0.019793926 | D7: ='Parameters 2'!I28 -> 900.09 | E7: ='Parameters 2'!I27 -> 892.06 | F7: -0.0089213301 | G7: -0.028538668 | H7: =H6*(1+G7) -> 73.056043
B8: 64.000494 | C8: -0.051286307 | D8: ='Parameters 2'!I29 -> 924.21 | E8: ='Parameters 2'!I28 -> 900.09 | F8: -0.026097965 | G8: -0.076045804 | H8: =H7*(1+G8) -> 67.500437
B9: 96.000494 | C9: -0.0067063214 | D9: ='Parameters 2'!I30 -> 930.23 | E9: ='Parameters 2'!I29 -> 924.21 | F9: -0.0064715178 | G9: -0.013134439 | H9: =H8*(1+G9) -> 66.613857
B10: 128.00049 | C10: 0.12869136 | D10: ='Parameters 2'!I31 -> 956.02 | E10: ='Parameters 2'!I30 -> 930.23 | F10: -0.026976423 | G10: 0.098243308 | H10: =H9*(1+G10) -> 73.158223
B11: 160.00049 | C11: 0.095552666 | D11: ='Parameters 2'!I32 -> 971.82 | E11: ='Parameters 2'!I31 -> 956.02 | F11: -0.016258155 | G11: 0.077741001 | H11: =H10*(1+G11) -> 78.845616
B12: 192.00049 | C12: 0.054410787 | D12: ='Parameters 2'!I33 -> 1000 | E12: ='Parameters 2'!I32 -> 971.82 | F12: -0.02818 | G12: 0.024697491 | H12: =H11*(1+G12) -> 80.792905
B13: 224.00049 | C13: 0.031159942 | D13: ='Parameters 2'!I34 -> 1035.2 | E13: ='Parameters 2'!I33 -> 1000 | F13: -0.034003091 | G13: -0.0039026832 | H13: =H12*(1+G13) -> 80.477596
B14: 256.00049 | C14: 0.017467249 | D14: ='Parameters 2'!I35 -> 1066.1 | E14: ='Parameters 2'!I34 -> 1035.2 | F14: -0.028984148 | G14: -0.012023172 | H14: =H13*(1+G14) -> 79.51
B15: 288.00049 | C15: -0.030429185 | D15: ='Parameters 2'!I36 -> 1067.24 | E15: ='Parameters 2'!I35 -> 1066.1 | F15: -0.0010681759 | G15: -0.031464857 | H15: =H14*(1+G15) -> 77.008229
B16: 320.00049 | C16: 0.050551104 | D16: ='Parameters 2'!I37 -> 1062.7 | E16: ='Parameters 2'!I36 -> 1067.24 | F16: 0.004272137 | G16: 0.055039203 | H16: =H15*(1+G16) -> 81.246701
B17: 352.00049 | C17: 0.055155269 | D17: ='Parameters 2'!I38 -> 1068.38 | E17: ='Parameters 2'!I37 -> 1062.7 | F17: -0.0053164604 | G17: 0.049545578 | H17: =H16*(1+G17) -> 85.272115
B20: Simulated Month to Month Returns - Hedged
B21: Month | C21: Foreign Asset Return | D21: Spot Exchange Rate (t) | E21: Spot Exchange Rate (t-1) | F21: Spot Exchange Return | G21: Risk Free Domestic | H21: Risk Free Foreign | I21: Forward | J21: Hedged Return | K21: Hedged Index | L21: Deviation
B22: {=_xlfn.SEQUENCE(12,1,1/1/2024,32)} -> 0.00049407115 | C22: {=_xlfn.ANCHORARRAY(C6)} -> -0.0066795949 | D22: ='Parameters 2'!I27 -> 892.06 | E22: ='Parameters 2'!I26 -> 675.36 | F22: {=E22:E33/D22:D33-1} -> -0.24292088 | G22: =+'Parameters 2'!$F$4 -> 0.0041666667 | H22: =+'Parameters 2'!$F$5 -> 0.026666667 | I22: =E22*(1+G22)/(1+H22) -> 660.55909 | J22: =(I22/E22)*(1+C22)-1 -> -0.028448792 | K22: =H4*(1+J22) -> 97.155121 | L22: =_xlfn.STDEV.S(K22:K33)/100 -> 0.065699839
B23: 32.000494 | C23: -0.019793926 | D23: ='Parameters 2'!I28 -> 900.09 | E23: ='Parameters 2'!I27 -> 892.06 | F23: -0.0089213301 | G23: =+'Parameters 2'!$F$4 -> 0.0041666667 | H23: =+'Parameters 2'!$F$5 -> 0.026666667 | I23: =E23*(1+G23)/(1+H23) -> 872.50998 | J23: =(I23/E23)*(1+C23)-1 -> -0.041275715 | K23: =K22*(1+J23) -> 93.144974
B24: 64.000494 | C24: -0.051286307 | D24: ='Parameters 2'!I29 -> 924.21 | E24: ='Parameters 2'!I28 -> 900.09 | F24: -0.026097965 | G24: =+'Parameters 2'!$F$4 -> 0.0041666667 | H24: =+'Parameters 2'!$F$5 -> 0.026666667 | I24: =E24*(1+G24)/(1+H24) -> 880.364 | J24: =(I24/E24)*(1+C24)-1 -> -0.072077922 | K24: =K23*(1+J24) -> 86.431278
B25: 96.000494 | C25: -0.0067063214 | D25: ='Parameters 2'!I30 -> 930.23 | E25: ='Parameters 2'!I29 -> 924.21 | F25: -0.0064715178 | G25: =+'Parameters 2'!$F$4 -> 0.0041666667 | H25: =+'Parameters 2'!$F$5 -> 0.026666667 | I25: =E25*(1+G25)/(1+H25) -> 903.9554 | J25: =(I25/E25)*(1+C25)-1 -> -0.028474933 | K25: =K24*(1+J25) -> 83.970153
B26: 128.00049 | C26: 0.12869136 | D26: ='Parameters 2'!I31 -> 956.02 | E26: ='Parameters 2'!I30 -> 930.23 | F26: -0.026976423 | G26: =+'Parameters 2'!$F$4 -> 0.0041666667 | H26: =+'Parameters 2'!$F$5 -> 0.026666667 | I26: =E26*(1+G26)/(1+H26) -> 909.84347 | J26: =(I26/E26)*(1+C26)-1 -> 0.10395543 | K26: =K25*(1+J26) -> 92.699306
B27: 160.00049 | C27: 0.095552666 | D27: ='Parameters 2'!I32 -> 971.82 | E27: ='Parameters 2'!I31 -> 956.02 | F27: -0.016258155 | G27: =+'Parameters 2'!$F$4 -> 0.0041666667 | H27: =+'Parameters 2'!$F$5 -> 0.026666667 | I27: =E27*(1+G27)/(1+H27) -> 935.06826 | J27: =(I27/E27)*(1+C27)-1 -> 0.071542989 | K27: =K26*(1+J27) -> 99.331292
B28: 192.00049 | C28: 0.054410787 | D28: ='Parameters 2'!I33 -> 1000 | E28: ='Parameters 2'!I32 -> 971.82 | F28: -0.02818 | G28: =+'Parameters 2'!$F$4 -> 0.0041666667 | H28: =+'Parameters 2'!$F$5 -> 0.026666667 | I28: =E28*(1+G28)/(1+H28) -> 950.522 | J28: =(I28/E28)*(1+C28)-1 -> 0.031302759 | K28: =K27*(1+J28) -> 102.44064
B29: 224.00049 | C29: 0.031159942 | D29: ='Parameters 2'!I34 -> 1035.2 | E29: ='Parameters 2'!I33 -> 1000 | F29: -0.034003091 | G29: =+'Parameters 2'!$F$4 -> 0.0041666667 | H29: =+'Parameters 2'!$F$5 -> 0.026666667 | I29: =E29*(1+G29)/(1+H29) -> 978.08442 | J29: =(I29/E29)*(1+C29)-1 -> 0.0085614696 | K29: =K28*(1+J29) -> 103.31768
B30: 256.00049 | C30: 0.017467249 | D30: ='Parameters 2'!I35 -> 1066.1 | E30: ='Parameters 2'!I34 -> 1035.2 | F30: -0.028984148 | G30: =+'Parameters 2'!$F$4 -> 0.0041666667 | H30: =+'Parameters 2'!$F$5 -> 0.026666667 | I30: =E30*(1+G30)/(1+H30) -> 1012.513 | J30: =(I30/E30)*(1+C30)-1 -> -0.0048311405 | K30: =K29*(1+J30) -> 102.81854
B31: 288.00049 | C31: -0.030429185 | D31: ='Parameters 2'!I36 -> 1067.24 | E31: ='Parameters 2'!I35 -> 1066.1 | F31: -0.0010681759 | G31: =+'Parameters 2'!$F$4 -> 0.0041666667 | H31: =+'Parameters 2'!$F$5 -> 0.026666667 | I31: =E31*(1+G31)/(1+H31) -> 1042.7358 | J31: =(I31/E31)*(1+C31)-1 -> -0.051677896 | K31: =K30*(1+J31) -> 97.50509
B32: 320.00049 | C32: 0.050551104 | D32: ='Parameters 2'!I37 -> 1062.7 | E32: ='Parameters 2'!I36 -> 1067.24 | F32: 0.004272137 | G32: =+'Parameters 2'!$F$4 -> 0.0041666667 | H32: =+'Parameters 2'!$F$5 -> 0.026666667 | I32: =E32*(1+G32)/(1+H32) -> 1043.8508 | J32: =(I32/E32)*(1+C32)-1 -> 0.027527663 | K32: =K31*(1+J32) -> 100.18918
B33: 352.00049 | C33: 0.055155269 | D33: ='Parameters 2'!I38 -> 1068.38 | E33: ='Parameters 2'!I37 -> 1062.7 | F33: -0.0053164604 | G33: =+'Parameters 2'!$F$4 -> 0.0041666667 | H33: =+'Parameters 2'!$F$5 -> 0.026666667 | I33: =E33*(1+G33)/(1+H33) -> 1039.4103 | J33: =(I33/E33)*(1+C33)-1 -> 0.032030925 | K33: =K32*(1+J33) -> 103.39833

Sheet PNL 2
B2: PNL 2 | K2: Index | O2: Row Labels | P2: Sum of Unhedged Index | Q2: Sum of Hedged Index
B3: Month | G3: Hedged | H3: Unhedged | K3: Month | L3: Unhedged Index | M3: Hedged Index | O3: 0.00049768519 | P3: 75.202214 | Q3: 97.155121
C4: {=+'Parameters 1'!H11:H22} -> January | G4: {=+'Currency Variance Scenario'!J22:J33} -> -0.028448792 | H4: {=+_xlfn.ANCHORARRAY('Currency Variance Scenario'!G6)} -> -0.24797786 | K4: {=+_xlfn.SEQUENCE(12,1,1/1/2024,31)} -> 0.00049407115 | L4: 75.202214 | M4: 97.155121 | O4: 31.000498 | P4: 73.056043 | Q4: 93.144974
C5: February | G5: -0.041275715 | H5: -0.028538668 | K5: 31.000494 | L5: 73.056043 | M5: 93.144974 | O5: 62.000498 | P5: 67.500437 | Q5: 86.431278
C6: March | G6: -0.072077922 | H6: -0.076045804 | K6: 62.000494 | L6: 67.500437 | M6: 86.431278 | O6: 93.000498 | P6: 66.613857 | Q6: 83.970153
C7: April | G7: -0.028474933 | H7: -0.013134439 | K7: 93.000494 | L7: 66.613857 | M7: 83.970153 | O7: 124.0005 | P7: 73.158223 | Q7: 92.699306
C8: May | G8: 0.10395543 | H8: 0.098243308 | K8: 124.00049 | L8: 73.158223 | M8: 92.699306 | O8: 155.0005 | P8: 78.845616 | Q8: 99.331292
C9: June | G9: 0.071542989 | H9: 0.077741001 | K9: 155.00049 | L9: 78.845616 | M9: 99.331292 | O9: 186.0005 | P9: 80.792905 | Q9: 102.44064
C10: July | G10: 0.031302759 | H10: 0.024697491 | K10: 186.00049 | L10: 80.792905 | M10: 102.44064 | O10: 217.0005 | P10: 80.477596 | Q10: 103.31768
C11: August | G11: 0.0085614696 | H11: -0.0039026832 | K11: 217.00049 | L11: 80.477596 | M11: 103.31768 | O11: 248.0005 | P11: 79.51 | Q11: 102.81854
C12: September | G12: -0.0048311405 | H12: -0.012023172 | K12: 248.00049 | L12: 79.51 | M12: 102.81854 | O12: 279.0005 | P12: 77.008229 | Q12: 97.50509
C13: October | G13: -0.051677896 | H13: -0.031464857 | K13: 279.00049 | L13: 77.008229 | M13: 97.50509 | O13: 310.0005 | P13: 81.246701 | Q13: 100.18918
C14: November | G14: 0.027527663 | H14: 0.055039203 | K14: 310.00049 | L14: 81.246701 | M14: 100.18918 | O14: 341.0005 | P14: 85.272115 | Q14: 103.39833
C15: December | G15: 0.032030925 | H15: 0.049545578 | K15: 341.00049 | L15: 85.272115 | M15: 103.39833 | O15: Grand Total | P15: 918.68394 | Q15: 1162.4016
B16: Cumulative | G16: =('Currency Variance Scenario'!K33-100)/100 -> 0.03398329 | H16: =('Currency Variance Scenario'!H17-100)/100 -> -0.14727885
