Workbook
Name company.name: Parms!$A$1
Name D.F.Interest.Expense: DebtSchedule!$K$18:$O$18
Name D.F.LTDebt: DebtSchedule!$K$22:$O$22
Name D.F.Revolver: DebtSchedule!$K$7:$O$7
Name D.F.STDebt: DebtSchedule!$K$21:$O$21
Name D.F.Sub.Debt: DebtSchedule!$K$8:$O$8
Name D.H.Interest.Expense: DebtSchedule!$G$18:$I$18
Name D.H.LTDebt: DebtSchedule!$G$22:$I$22
Name D.H.STDebt: DebtSchedule!$G$21:$I$21
Name D.Rate.Revolver: DebtSchedule!$K$15:$O$15
Name D.Rate.Sub.Debt: DebtSchedule!$K$16:$O$16
Name dates.forecast: Parms!$J$1:$N$1
Name dates.hist: Parms!$G$1:$I$1
Name DCF.Cash: 'Financial Statements'!$I$46
Name DCF.Debt: DebtSchedule!$I$9
Name DCF.Discount.Cash.Flow: 'DCF Analysis'!$G$26:$K$26
Name DCF.Equity: 'Financial Statements'!$I$82
Name DCF.Interest.Expense: DebtSchedule!$I$18
Name DCF.NPV.DCF: 'DCF Analysis'!$G$28
Name DCF.Pref.Stock: 'Financial Statements'!$I$78
Name DCF.Terminal.Discount.Factor: 'DCF Analysis'!$K$25
Name DCF.Terminal.EBITDA: 'DCF Analysis'!$K$15
Name DCF.Terminal.Free.Cash.Flow: 'DCF Analysis'!$K$24
Name DCF.Undiscounted.Cash.Flow: 'DCF Analysis'!$G$24:$K$24
Name EBITDA.LBO: 'Transaction Summary'!$G$3
Name F.Capital: 'Financial Statements'!$K$84:$O$84
Name F.Cash: 'Financial Statements'!$K$117:$O$117
Name F.Cash.Financing: 'Financial Statements'!$K$113:$O$113
Name F.Cash.Investment: 'Financial Statements'!$K$106:$O$106
Name F.Cash.Ops: 'Financial Statements'!$K$101:$O$101
Name F.COGS: 'Financial Statements'!$K$13:$O$13
Name F.EBIT: 'Financial Statements'!$K$28:$O$28
Name F.EBT: 'Financial Statements'!$K$33:$O$33
Name F.Equity: 'Financial Statements'!$K$82:$O$82
Name F.Fixed.Costs: 'Financial Statements'!$K$26:$O$26
Name F.Gross.Margin: 'Financial Statements'!$K$15:$O$15
Name F.Net.Income: 'Financial Statements'!$K$37:$O$37
Name F.Revenues: 'Financial Statements'!$K$7:$O$7
Name F.STarting.Cash: 'Financial Statements'!$K$116:$O$116
Name F.Total.Assets: 'Financial Statements'!$K$60:$O$60
Name FCF.Labels: 'DCF Analysis'!$C$15:$F$24
Name FCF.Values: 'DCF Analysis'!$G$15:$K$24
Name Final.Amortization.Expense: 'Financial Statements'!$I$25
Name Final.Depreciation.Expense: 'Financial Statements'!$I$24
Name Final.EBIT: 'Financial Statements'!$I$28
Name goldman.sachs.fee: 'Transaction Summary'!$G$19
Name H.Capital: 'Financial Statements'!$G$84:$I$84
Name H.Cash: 'Financial Statements'!$G$117:$I$117
Name H.Cash.Financing: 'Financial Statements'!$H$113:$I$113
Name H.Cash.From.Ops: 'Financial Statements'!$H$101:$I$101
Name H.Cash.Investment: 'Financial Statements'!$H$106:$I$106
Name H.COGS: 'Financial Statements'!$G$13:$I$13
Name H.EBIT: 'Financial Statements'!$G$28:$I$28
Name H.Fixed.Costs: 'Financial Statements'!$G$26:$I$26
Name H.Gross.Margin: 'Financial Statements'!$G$15:$I$15
Name H.Net.Income: 'Financial Statements'!$G$37:$I$37
Name H.Operating.Income: 'Financial Statements'!$G$28:$I$28
Name H.Revenues: 'Financial Statements'!$G$7:$I$7
Name H.Total.Assets: 'Financial Statements'!$G$60:$I$60
Name JPM.Fee: 'Transaction Summary'!$R$8

Sheet Parms
A1: Legends Inc. | G1: {=_xlfn.SEQUENCE(1,8,2022,1)} -> 2022 | H1: 2023 | I1: 2024 | J1: 2025 | K1: 2026 | L1: 2027 | M1: 2028 | N1: 2029
B2: Revenues
C3: Foot Solutions | G3: 8399 | H3: 8791 | I3: 8433 | J3: =+I3*(1+J7) -> 8719.722 | K3: =+J3*(1+K7) -> 9016.1925 | L3: =+K3*(1+L7) -> 9322.7431 | M3: =+L3*(1+M7) -> 9639.7164 | N3: =+M3*(1+N7) -> 9967.4667
C4: Greeting Fulfillments | G4: 8696 | H4: 8327 | I4: 8537 | J4: =+I4*(1+J8) -> 8852.869 | K4: =+J4*(1+K8) -> 9180.4252 | L4: =+K4*(1+L8) -> 9520.1009 | M4: =+L4*(1+M8) -> 9872.3446 | N4: =+M4*(1+N8) -> 10237.621
C5: Legendwear | G5: 8366 | H5: 8657 | I5: 8501 | J5: =+I5*(1+J9) -> 8832.539 | K5: =+J5*(1+K9) -> 9177.008 | L5: =+K5*(1+L9) -> 9534.9113 | M5: =+L5*(1+M9) -> 9906.7729 | N5: =+M5*(1+N9) -> 10293.137
B6: % Change
C7: {=+C3:C5} -> Foot Solutions | H7: 0.046672223 | I7: -0.040723467 | J7: 0.034 | K7: =+J7 -> 0.034 | L7: =AVERAGE(J7:K7) -> 0.034 | M7: =AVERAGE(K7:L7) -> 0.034 | N7: =AVERAGE(L7:M7) -> 0.034
C8: Greeting Fulfillments | H8: -0.042433303 | I8: 0.025219167 | J8: 0.037 | K8: =+J8 -> 0.037 | L8: =AVERAGE(J8:K8) -> 0.037 | M8: =AVERAGE(K8:L8) -> 0.037 | N8: =AVERAGE(L8:M8) -> 0.037
C9: Legendwear | H9: 0.034783648 | I9: -0.018020099 | J9: 0.039 | K9: =+J9 -> 0.039 | L9: =AVERAGE(J9:K9) -> 0.039 | M9: =AVERAGE(K9:L9) -> 0.039 | N9: =AVERAGE(L9:M9) -> 0.039
B10: Cost of Goods Sold
C11: {=+C3:C5} -> Foot Solutions | G11: 0.52854836 | H11: 0.51945532 | I11: 0.52962561 | J11: =AVERAGE(G11:I11) -> 0.52587643 | K11: =AVERAGE(H11:J11) -> 0.52498579 | L11: =AVERAGE(I11:K11) -> 0.52682928 | M11: =AVERAGE(J11:L11) -> 0.52589717 | N11: =AVERAGE(K11:M11) -> 0.52590408
C12: Greeting Fulfillments | G12: 0.54951212 | H12: 0.50621255 | I12: 0.54249378 | J12: =AVERAGE(G12:I12) -> 0.53273948 | K12: =AVERAGE(H12:J12) -> 0.5271486 | L12: =AVERAGE(I12:K12) -> 0.53412729 | M12: =AVERAGE(J12:L12) -> 0.53133846 | N12: =AVERAGE(K12:M12) -> 0.53087145
C13: Legendwear | G13: 0.50169648 | H13: 0.51854696 | I13: 0.53504035 | J13: =AVERAGE(G13:I13) -> 0.51842793 | K13: =AVERAGE(H13:J13) -> 0.52400508 | L13: =AVERAGE(I13:K13) -> 0.52582446 | M13: =AVERAGE(J13:L13) -> 0.52275249 | N13: =AVERAGE(K13:M13) -> 0.52419401
B14: Operating Expenses (aka fixed costs)
C15: Rent | G15: 0.04520141 | H15: 0.041519682 | I15: 0.041485585 | J15: 0.041 | K15: =AVERAGE(H15:J15) -> 0.041335089 | L15: =AVERAGE(I15:K15) -> 0.041273558 | M15: =AVERAGE(J15:L15) -> 0.041202882 | N15: =AVERAGE(K15:M15) -> 0.04127051
C16: Utilities | G16: 0.039664353 | H16: 0.04825251 | I16: 0.0428629 | J16: 0.043 | K16: =AVERAGE(H16:J16) -> 0.044705137 | L16: =AVERAGE(I16:K16) -> 0.043522679 | M16: =AVERAGE(J16:L16) -> 0.043742605 | N16: =AVERAGE(K16:M16) -> 0.04399014
C17: Phone | G17: 0.030733282 | H17: 0.037306794 | I17: 0.041556613 | J17: =AVERAGE(G17:I17) -> 0.03653223 | K17: =AVERAGE(H17:J17) -> 0.038465212 | L17: =AVERAGE(I17:K17) -> 0.038851352 | M17: =AVERAGE(J17:L17) -> 0.037949598 | N17: =AVERAGE(K17:M17) -> 0.038422054
C18: Advertising | G18: 0.031545546 | H18: 0.037579353 | I18: 0.036485053 | J18: =AVERAGE(G18:I18) -> 0.035203317 | K18: =AVERAGE(H18:J18) -> 0.036422575 | L18: =AVERAGE(I18:K18) -> 0.036036982 | M18: =AVERAGE(J18:L18) -> 0.035887625 | N18: =AVERAGE(K18:M18) -> 0.036115727
C19: Salaries | G19: 0.037692894 | H19: 0.046375124 | I19: 0.033670329 | J19: 0.036 | K19: =+J19 -> 0.036 | L19: =AVERAGE(I19:K19) -> 0.035223443 | M19: =AVERAGE(J19:L19) -> 0.035741148 | N19: =AVERAGE(K19:M19) -> 0.035654864
C20: Depreciation Expense | G20: 1000 | H20: =+G20 -> 1000 | I20: =+H20 -> 1000 | J20: =+I20 -> 1000 | K20: =+J20 -> 1000 | L20: =+K20 -> 1000 | M20: =+L20 -> 1000 | N20: =+M20 -> 1000
C21: Amortization Expense | G21: 250 | H21: =+G21 -> 250 | I21: =+H21 -> 250 | J21: =+I21+LBO.Goodwill/20 -> 2841.0598 | K21: =+J21 -> 2841.0598 | L21: =+K21 -> 2841.0598 | M21: =+L21 -> 2841.0598 | N21: =+M21 -> 2841.0598
B22: Tax Rate | G22: 0.21
B23: Cash Dividends | G23: 1500 | H23: =+G23 -> 1500 | I23: =+H23 -> 1500 | J23: 0 | K23: =+J23 -> 0 | L23: =+K23 -> 0 | M23: =+L23 -> 0 | N23: =+M23 -> 0
B24: Stock Buybacks | G24: 500 | H24: =+G24 -> 500 | I24: =+H24 -> 500 | J24: 0 | K24: =+J24 -> 0 | L24: =+K24 -> 0 | M24: =+L24 -> 0 | N24: =+M24 -> 0
B25: Balance Sheet
C26: Working Capital
D27: Accounts Receivable (days of Sales) | G27: 60 | H27: =+G27 -> 60 | I27: =+H27 -> 60 | J27: 55 | K27: 50 | L27: 45 | M27: 43 | N27: =+M27 -> 43
D28: Inventory (days of COGS) | G28: 32 | H28: =+G28 -> 32 | I28: =+H28 -> 32 | J28: 28 | K28: 26 | L28: 24 | M28: 23 | N28: =+M28 -> 23
D29: Prepaid Expenses | G29: 0.03 | H29: =+G29 -> 0.03 | I29: =+H29 -> 0.03 | J29: =+I29 -> 0.03 | K29: =+J29 -> 0.03 | L29: =+K29 -> 0.03 | M29: =+L29 -> 0.03 | N29: =+M29 -> 0.03
D30: Accounts Payable (days COGS) | G30: 35 | H30: =+G30 -> 35 | I30: =+H30 -> 35 | J30: 40 | K30: 45 | L30: =+K30 -> 45 | M30: 47 | N30: =+M30 -> 47
D31: Accrued Liabilities | G31: 0.03 | H31: =+G31 -> 0.03 | I31: =+H31 -> 0.03 | J31: =+I31 -> 0.03 | K31: =+J31 -> 0.03 | L31: =+K31 -> 0.03 | M31: =+L31 -> 0.03 | N31: =+M31 -> 0.03
C32: Capital Expenditure (CAPEX) | H32: 2500 | I32: =+H32 -> 2500 | J32: 1750 | K32: =+J32 -> 1750 | L32: =+K32 -> 1750 | M32: =+L32 -> 1750 | N32: =+M32 -> 1750
C33: Starting Gross PP&E | G33: 6000
C34: Starting Accumulated Depreciation | G34: 1500
C35: Starting.Goodwill | G35: 2000
C36: Starting Cash | G36: 4500

Sheet LBO Returns
A1: LBO Returns Calculation
B2: Weighted Average Cost of Capital (WACC) Post LBO
C3: Capital | G3: {=+dates.forecast} -> 2025 | H3: 2026 | I3: 2027 | J3: 2028 | K3: 2029
D4: Revolver | G4: {=D.F.Revolver} -> 18500 | H4: 16603.763 | I4: 14303.886 | J4: 11645.471 | K4: 8713.3719
D5: Subordinated Debt | G5: {=D.F.Sub.Debt} -> 20000 | H5: 20000 | I5: 20000 | J5: 20000 | K5: 20000
D6: Equity | G6: {=F.Equity} -> 30001.093 | H6: 30328.966 | I6: 30978.917 | J6: 32075.321 | K6: 33552.851
C7: Total Capital | G7: =SUM(G4:G6) -> 68501.093 | H7: =SUM(H4:H6) -> 66932.729 | I7: =SUM(I4:I6) -> 65282.803 | J7: =SUM(J4:J6) -> 63720.792 | K7: =SUM(K4:K6) -> 62266.222
C8: Weights
D9: {=+D4:D6} -> Revolver | G9: {=_xlfn.ANCHORARRAY(G4)/$G$7:$K$7} -> 0.27006869 | H9: 0.24806643 | I9: 0.21910649 | J9: 0.18275779 | K9: 0.13993738
D10: Subordinated Debt | G10: {=_xlfn.ANCHORARRAY(G5)/$G$7:$K$7} -> 0.29196615 | H10: 0.29880748 | I10: 0.3063594 | J10: 0.31386929 | K10: 0.32120143
D11: Equity | G11: {=_xlfn.ANCHORARRAY(G6)/$G$7:$K$7} -> 0.43796517 | H11: 0.45312609 | I11: 0.47453412 | J11: 0.50337291 | K11: 0.53886119
C12: After-Tax Costs Of Capital
D13: {=+_xlfn.ANCHORARRAY(D9)} -> Revolver | G13: {=D.Rate.Revolver*(1-tax.rate)} -> 0.05925 | H13: 0.05925 | I13: 0.05925 | J13: 0.05925 | K13: 0.05925
D14: Subordinated Debt | G14: {=D.Rate.Sub.Debt*(1-tax.rate)} -> 0.08295 | H14: 0.08295 | I14: 0.08295 | J14: 0.08295 | K14: 0.08295
D15: Equity | G15: 0.2617 | H15: =+G15 -> 0.2617 | I15: =+H15 -> 0.2617 | J15: =+I15 -> 0.2617 | K15: =+J15 -> 0.2617
C16: WACC | G16: =SUMPRODUCT(G9:G11,G13:G15) -> 0.15483565 | H16: =SUMPRODUCT(H9:H11,H13:H15) -> 0.15806711 | I16: =SUMPRODUCT(I9:I11,I13:I15) -> 0.16258015 | J16: =SUMPRODUCT(J9:J11,J13:J15) -> 0.16859655 | K16: =SUMPRODUCT(K9:K11,K13:K15) -> 0.17595492
C17: Discount Factors
D18: 1-Year Factors | G18: {=1/(1+G16:K16)} -> 0.86592408 | H18: 0.86350781 | I18: 0.86015575 | J18: 0.85572733 | K18: 0.85037273
D19: Multi-Year Discount | G19: =PRODUCT($G18:G18) -> 0.86592408 | H19: =PRODUCT($G18:H18) -> 0.74773221 | I19: =PRODUCT($G18:I18) -> 0.64316616 | J19: =PRODUCT($G18:J18) -> 0.55037486 | K19: =PRODUCT($G18:K18) -> 0.46802377
B21: Unlevered Free Cash Flow | G21: {=+dates.forecast} -> 2025 | H21: 2026 | I21: 2027 | J21: 2028 | K21: 2029
C22: EBITDA | G22: {=FCF.Values} -> 7461.5239 | H22: 7601.3719 | I22: 7836.5742 | J22: 8202.3227 | K22: 8464.8535
D23: Less: Depreciation and Amortization | G23: -3841.0598 | H23: -3841.0598 | I23: -3841.0598 | J23: -3841.0598 | K23: -3841.0598
C24: EBIT | G24: 3620.4641 | H24: 3760.3121 | I24: 3995.5144 | J24: 4361.2629 | K24: 4623.7937
D25: tax rate | G25: 0.21 | H25: 0.21 | I25: 0.21 | J25: 0.21 | K25: 0.21
C26: EBIAT (NOPAT - Net Op Profit After Tax) | G26: 2860.1666 | H26: 2970.6466 | I26: 3156.4563 | J26: 3445.3977 | K26: 3652.797
D27: Add back: Depr & Amort | G27: 3841.0598 | H27: 3841.0598 | I27: 3841.0598 | J27: 3841.0598 | K27: 3841.0598
D28: Working Capital Change | G28: 552.35495 | H28: 521.32054 | I28: 366.14857 | J28: 188.0239 | K28: -89.119715
C29: Unlevered Cash From Operations | G29: 7253.5814 | H29: 7333.0269 | I29: 7363.6647 | J29: 7474.4814 | K29: 7404.7371
D30: Less: CAPEX | G30: -1750 | H30: -1750 | I30: -1750 | J30: -1750 | K30: -1750
C31: Unlevered Free Cash Flow | G31: 5503.5814 | H31: 5583.0269 | I31: 5613.6647 | J31: 5724.4814 | K31: 5654.7371
B33: Valuation
C34: Discount Factors | G34: {=+G19:K19} -> 0.86592408 | H34: 0.74773221 | I34: 0.64316616 | J34: 0.55037486 | K34: 0.46802377
C35: Discounted Unlevered FCF From Operations | G35: {=+G31:K31*_xlfn.ANCHORARRAY(G34)} -> 4765.6837 | H35: 4174.6091 | I35: 3610.5192 | J35: 3150.6107 | K35: 2646.5514
B37: Equity Calculations
G38: Exit Multiplier | H38: Terminal Enterprise Value | I38: Plus: Terminal Cash | J38: Less: Terminal Debt | K38: Terminal Equity Value | L38: PV TEV
G39: {=_xlfn.SEQUENCE(4,1,8,2)} -> 8 | H39: {=+_xlfn.ANCHORARRAY(G39)*LBO.Terminal.EBITDA} -> 67718.828 | I39: =+LBO.Terminal.Cash -> 9364.1988 | J39: =-Terminal.Debt -> -28713.372 | K39: =SUM(H39:J39) -> 48369.655 | L39: {=+K39:K42*Terminal.Discount.Factor} -> 22638.148
G40: 10 | H40: 84648.535 | I40: =+I39 -> 9364.1988 | J40: =+J39 -> -28713.372 | K40: =SUM(H40:J40) -> 65299.362 | L40: 30561.654
G41: 12 | H41: 101578.24 | I41: =+I40 -> 9364.1988 | J41: =+J40 -> -28713.372 | K41: =SUM(H41:J41) -> 82229.069 | L41: 38485.159
G42: 14 | H42: 118507.95 | I42: =+I41 -> 9364.1988 | J42: =+J41 -> -28713.372 | K42: =SUM(H42:J42) -> 99158.776 | L42: 46408.664
B43: Gecko's Performance
...

Sheet Transaction Summary
A1: Transaction Summary
B2: Valuation | I2: Sources and Uses of Cash
C3: EBITDA | G3: =Final.EBIT+Final.Amortization.Expense+Final.Depreciation.Expense -> 6831.1633 | J3: Sources | N3: $ | O3: % | P3: xEBITDA | Q3: Fee% | R3: Fee$
C4: Multiple | G4: 9.5 | K4: Balance Sheet Cash | N4: =DCF.Cash -> 3808.152 | O4: =+N4/$N$8 -> 0.048447181 | P4: =N4/EBITDA.LBO -> 0.55746758
D5: Enterprise Value | G5: =+G3*G4 -> 64896.051 | K5: Revolver | N5: 20000 | O5: =+N5/$N$8 -> 0.25443932 | P5: =N5/EBITDA.LBO -> 2.927759 | Q5: 0.03 | R5: =Q5*N5 -> 600
C6: Capitalization | K6: Subordinated Debt | N6: 20000 | O6: =+N6/$N$8 -> 0.25443932 | P6: =N6/EBITDA.LBO -> 2.927759 | Q6: 0.04 | R6: =Q6*N6 -> 800
D7: Less | K7: Sponsor Equity (Gecko Fund) | N7: =40000-5493+0.050895+289 -> 34796.051 | O7: =+N7/$N$8 -> 0.44267418 | P7: =N7/EBITDA.LBO -> 5.0937226
E8: Debt | G8: =-DCF.Debt -> -5500 | J8: Total Sources | N8: =SUM(N4:N7) -> 78604.203 | R8: =SUM(R4:R7) -> 1400
E9: Preferred Stock | G9: =-DCF.Pref.Stock -> -1500
D10: Add | J10: Uses
E11: Cash | G11: =+DCF.Cash -> 3808.152 | K11: Minimum Cash Balance | N11: =minimum.cash.balance -> 5000
C12: Net Offer Value to Shareholders | G12: =SUM(G5:G11) -> 61704.203 | K12: Purchase of Equity | N12: =G12 -> 61704.203
D13: Offer Per Share | G13: =G12/shares.outstanding -> 108.17429 | K13: Retire Debt | N13: =+DCF.Debt -> 5500
K14: Retire Pref Stock | N14: =+DCF.Pref.Stock -> 1500
B15: Other Assumptions | K15: M&A Fee | N15: =+goldman.sachs.fee -> 3500
C16: Revolver EBITDA Borrowing Base Multiplier | G16: 6 | K16: Debt Placement Fee | N16: =+JPM.Fee -> 1400
C17: Revolver Availability @ Close | G17: =G16*G3 -> 40986.98 | J17: Total Uses | N17: =SUM(N11:N16) -> 78604.203
C18: Minimum Cash Balance | G18: 5000 | K18: Checksum | N18: =N8-N17 -> 2.4106703e-07
C19: Fee: Mergers and Acquisitions Fee | G19: 3500
B21: Goodwill Calculation
C22: Purchase of Equity | G22: =+G12 -> 61704.203
D23: Less: Book Value of Assets | G23: =-(DCF.Equity-DCF.Pref.Stock) -> -9883.007
C24: Goodwill | G24: =SUM(G22,G23) -> 51821.196

Sheet Financial Statements
A1: =company.name&" Financial Statements" -> Legends Inc. Financial Statements
B2: Income Statement | G2: {=dates.hist} -> 2022 | H2: 2023 | I2: 2024 | J2: LBO | K2: {=dates.forecast} -> 2025 | L2: 2026 | M2: 2027 | N2: 2028 | O2: 2029
C3: Revenues
D4: {=+Parms!C3:C5} -> Foot Solutions | G4: {=P.H.Revenues} -> 8399 | H4: 8791 | I4: 8433 | K4: {=P.F.Revenues} -> 8719.722 | L4: 9016.1925 | M4: 9322.7431 | N4: 9639.7164 | O4: 9967.4667
D5: Greeting Fulfillments | G5: 8696 | H5: 8327 | I5: 8537 | K5: 8852.869 | L5: 9180.4252 | M5: 9520.1009 | N5: 9872.3446 | O5: 10237.621
D6: Legendwear | G6: 8366 | H6: 8657 | I6: 8501 | K6: 8832.539 | L6: 9177.008 | M6: 9534.9113 | N6: 9906.7729 | O6: 10293.137
C7: Total Revenues | G7: =SUM(G4:G6) -> 25461 | H7: =SUM(H4:H6) -> 25775 | I7: =SUM(I4:I6) -> 25471 | K7: =SUM(K4:K6) -> 26405.13 | L7: =SUM(L4:L6) -> 27373.626 | M7: =SUM(M4:M6) -> 28377.755 | N7: =SUM(N4:N6) -> 29418.834 | O7: =SUM(O4:O6) -> 30498.225
C9: Cost of Goods Sold
D10: {=+_xlfn.ANCHORARRAY(D4)} -> Foot Solutions | G10: {=P.H.COGS*P.H.Revenues} -> 4439.2777 | H10: 4566.5317 | I10: 4466.3328 | K10: {=P.F.Revenues*P.F.COGS} -> 4585.4963 | L10: 4733.3729 | M10: 4911.494 | N10: 5069.4995 | O10: 5241.9314
D11: Greeting Fulfillments | G11: 4778.5574 | H11: 4215.2319 | I11: 4631.2694 | K11: 4716.2728 | L11: 4839.4483 | M11: 5084.9457 | N11: 5245.5564 | O11: 5434.8609
D12: Legendwear | G12: 4197.1927 | H12: 4489.061 | I12: 4548.3781 | K12: 4579.0349 | L12: 4808.7988 | M12: 5013.6896 | N12: 5178.7902 | O12: 5395.6008
C13: Total Cost of Goods Sold | G13: =SUM(G10:G12) -> 13415.028 | H13: =SUM(H10:H12) -> 13270.825 | I13: =SUM(I10:I12) -> 13645.98 | K13: =SUM(K10:K12) -> 13880.804 | L13: =SUM(L10:L12) -> 14381.62 | M13: =SUM(M10:M12) -> 15010.129 | N13: =SUM(N10:N12) -> 15493.846 | O13: =SUM(O10:O12) -> 16072.393
C15: Gross Margin | G15: {=H.Revenues-H.COGS} -> 12045.972 | H15: 12504.175 | I15: 11825.02 | K15: {=F.Revenues-F.COGS} -> 12524.326 | L15: 12992.006 | M15: 13367.626 | N15: 13924.988 | O15: 14425.832
D16: % Revenues | G16: {=H.Gross.Margin/H.Revenues} -> 0.47311465 | H16: 0.48512805 | I16: 0.46425424 | K16: {=F.Gross.Margin/F.Revenues} -> 0.47431412 | L16: 0.47461764 | M16: 0.47106002 | N16: 0.47333582 | O16: 0.47300563
C18: Selling, General and Administrative Expenses (SG&A)(aka Operating Expenses)
D19: Rent | G19: {=H.Revenues*P.H.Fixed.Costs} -> 1150.8731 | H19: 1070.1698 | I19: 1056.6793 | K19: {=F.Revenues*P.F.Fixed.Costs} -> 1082.6103 | L19: 1131.4913 | M19: 1171.2509 | N19: 1212.1408 | O19: 1258.6773
D20: Utilities | G20: 1009.8941 | H20: 1243.7085 | I20: 1091.7609 | K20: 1135.4206 | L20: 1223.7417 | M20: 1235.0759 | N20: 1286.8564 | O20: 1341.6212
D21: Phone | G21: 782.5001 | H21: 961.58261 | I21: 1058.4885 | K21: 964.63828 | L21: 1052.9323 | M21: 1102.5142 | N21: 1116.4329 | O21: 1171.8045
D22: Advertising | G22: 803.18113 | H22: 968.60783 | I22: 929.3108 | K22: 929.54817 | L22: 997.01793 | M22: 1022.6487 | N22: 1055.7721 | O22: 1101.4656
D23: Salaries | G23: 959.69878 | H23: 1195.3188 | I23: 857.61694 | K23: 950.58468 | L23: 985.45053 | M23: 999.56224 | N23: 1051.4629 | O23: 1087.4101
D24: Depreciation Expense | G24: {=P.H.Depreciation.Expense} -> 1000 | H24: 1000 | I24: 1000 | K24: {=P.F.Depreciation.Expense} -> 1000 | L24: 1000 | M24: 1000 | N24: 1000 | O24: 1000
D25: Amortization Expense | G25: {=P.H.Amortization.Expense} -> 250 | H25: 250 | I25: 250 | K25: {=P.F.Amortization.Expense} -> 2841.0598 | L25: 2841.0598 | M25: 2841.0598 | N25: 2841.0598 | O25: 2841.0598
C26: Total SG&A Expenses | G26: =SUM(G19:G25) -> 5956.1472 | H26: =SUM(H19:H25) -> 6689.3875 | I26: =SUM(I19:I25) -> 6243.8565 | K26: =SUM(K19:K25) -> 8903.8618 | L26: =SUM(L19:L25) -> 9231.6935 | M26: =SUM(M19:M25) -> 9372.1117 | N26: =SUM(N19:N25) -> 9563.7248 | O26: =SUM(O19:O25) -> 9802.0384
C28: Earnings Before Interest and Taxes (EBIT) | G28: {=H.Gross.Margin-H.Fixed.Costs} -> 6089.825 | H28: 5814.7879 | I28: 5581.1633 | K28: {=F.Gross.Margin-F.Fixed.Costs} -> 3620.4641 | L28: 3760.3121 | M28: 3995.5144 | N28: 4361.2629 | O28: 4623.7937
D29: % Revenues | G29: {=H.Operating.Income/H.Revenues} -> 0.23918248 | H29: 0.22559798 | I29: 0.21911834 | K29: {=F.EBIT/F.Revenues} -> 0.13711215 | L29: 0.1373699 | M29: 0.14079741 | N29: 0.14824731 | O29: 0.15160862
C31: Interest Expense | G31: {=D.H.Interest.Expense} -> 525.5 | H31: 509.375 | I31: 370.25 | K31: {=D.F.Interest.Expense} -> 3487.5 | L31: 3345.2822 | M31: 3172.7914 | N31: 2973.4103 | O31: 2753.5029
C33: Earnings Before Taxes (EBT) | G33: {=H.EBIT-G31:I31} -> 5564.325 | H33: 5305.4129 | I33: 5210.9133 | K33: {=+F.EBIT-D.F.Interest.Expense} -> 132.9641 | L33: 415.02989 | M33: 822.72294 | N33: 1387.8526 | O33: 1870.2908
C35: Income Tax Expense | G35: {=+_xlfn.ANCHORARRAY(G33)*tax.rate} -> 1168.5082 | H35: 1114.1367 | I35: 1094.2918 | K35: {=F.EBT*tax.rate} -> 27.922461 | L35: 87.156276 | M35: 172.77182 | N35: 291.44904 | O35: 392.76107
C37: Net Income | G37: {=+_xlfn.ANCHORARRAY(G33)-_xlfn.ANCHORARRAY(G35)} -> 4395.8167 | H37: 4191.2762 | I37: 4116.6215 | K37: {=+F.EBT-_xlfn.ANCHORARRAY(K35)} -> 105.04164 | L37: 327.87361 | M37: 649.95113 | N37: 1096.4035 | O37: 1477.5297
C39: Less: Cash Dividends | G39: {=-P.H.Dividends} -> -1500 | H39: -1500 | I39: -1500 | K39: {=-P.F.Dividends} -> 0 | L39: 0 | M39: 0 | N39: 0 | O39: 0
C40: Change in Retained Earnings | G40: {=+_xlfn.ANCHORARRAY(G37)+_xlfn.ANCHORARRAY(G39)} -> 2895.8167 | H40: 2691.2762 | I40: 2616.6215 | K40: {=F.Net.Income+_xlfn.ANCHORARRAY(K39)} -> 105.04164 | L40: 327.87361 | M40: 649.95113 | N40: 1096.4035 | O40: 1477.5297
B43: Balance Sheet | G43: {=dates.hist} -> 2022 | H43: 2023 | I43: 2024 | J43: LBO | K43: {=dates.forecast} -> 2025 | L43: 2026 | M43: 2027 | N43: 2028 | O43: 2029
C44: Assets
D45: Short Term Assets
E46: Cash | G46: {=H.Cash} -> 4500 | H46: 5138.4745 | I46: 3808.152 | J46: =minimum.cash.balance -> 5000 | K46: {=F.Cash} -> 6248.4564 | L46: 7292.4736 | M46: 8099.7554 | N46: 8816.8284 | O46: 9364.1988
E47: Accounts Receivable | G47: {=H.Revenues*(P.H.Accounts.Rec.Days/365)} -> 4185.3699 | H47: 4236.9863 | I47: 4187.0137 | J47: =+I47 -> 4187.0137 | K47: {=F.Revenues*(P.F.Accts.Rec.Days/365)} -> 3978.8552 | L47: 3749.8117 | M47: 3498.6274 | N47: 3465.7804 | O47: 3592.9416
E48: Inventory | G48: {=H.COGS*(P.H.Inventory.Days/365)} -> 1176.112 | H48: 1163.4696 | I48: 1196.3599 | J48: =+I48 -> 1196.3599 | K48: {=F.COGS*(P.F.Inventory.Days/365)} -> 1064.8288 | L48: 1024.4442 | M48: 986.9674 | N48: 976.32455 | O48: 1012.7809
E49: Prepaid Expenses | G49: {=P.H.Prepaids*H.Revenues} -> 763.83 | H49: 773.25 | I49: 764.13 | J49: =+I49 -> 764.13 | K49: {=P.F.Prepaids*F.Revenues} -> 792.1539 | L49: 821.20877 | M49: 851.33266 | N49: 882.56502 | O49: 914.94675
D50: Total Short Term Assets | G50: =SUM(G46:G49) -> 10625.312 | H50: =SUM(H46:H49) -> 11312.18 | I50: =SUM(I46:I49) -> 9955.6556 | J50: =SUM(J46:J49) -> 11147.504 | K50: =SUM(K46:K49) -> 12084.294 | L50: =SUM(L46:L49) -> 12887.938 | M50: =SUM(M46:M49) -> 13436.683 | N50: =SUM(N46:N49) -> 14141.498 | O50: =SUM(O46:O49) -> 14884.868
D52: Long Term Assets
...

Sheet DCF Analysis
A1: ="Discount Cash Flow Model for "&company.name -> Discount Cash Flow Model for Legends Inc.
B2: General Assumptions
C3: Share Price @ Last Close | G3: {=+_FV(H3,"Price")} -> 10.375 | H3: #VALUE!
C4: Shares Outstanding (mm's) | G4: {=_FV(H3,"Shares outstanding",TRUE)/1000000} -> 570.4147
C5: Market Capitaliztion ($mm's) | G5: {=+_FV(H3,"Market cap",TRUE)/1000000} -> 5918.0525
B7: Weighted Averaged Cost of Capital (WACC) | G7: Amount | H7: Weight | I7: Cost
C8: Debt | G8: =DCF.Debt -> 5500 | H8: =+G8/$G$11 -> 0.32577135 | I8: =+(DCF.Interest.Expense/DCF.Debt)*(1-tax.rate) -> 0.053181364
C9: Preferred Stock | G9: =DCF.Pref.Stock -> 1500 | H9: =+G9/$G$11 -> 0.088846732 | I9: 0.0773
C10: Common Stock (aka Equity) | G10: =DCF.Equity-DCF.Pref.Stock -> 9883.007 | H10: =+G10/$G$11 -> 0.58538192 | I10: 0.1883
G11: =SUM(G8:G10) -> 16883.007
B12: WACC | G12: =SUMPRODUCT(H8:H10,I8:I10) -> 0.13442023
B14: Free Cash Flow Buildup | G14: {=dates.forecast} -> 2025 | H14: 2026 | I14: 2027 | J14: 2028 | K14: 2029
C15: EBITDA | G15: {=_xlfn.ANCHORARRAY(G17)-_xlfn.ANCHORARRAY(G16)} -> 7461.5239 | H15: 7601.3719 | I15: 7836.5742 | J15: 8202.3227 | K15: 8464.8535
D16: Less: Depreciation and Amortization | G16: {=-P.F.Depreciation.Expense-P.F.Amortization.Expense} -> -3841.0598 | H16: -3841.0598 | I16: -3841.0598 | J16: -3841.0598 | K16: -3841.0598
C17: EBIT | G17: {=F.EBIT} -> 3620.4641 | H17: 3760.3121 | I17: 3995.5144 | J17: 4361.2629 | K17: 4623.7937
D18: tax rate | G18: =tax.rate -> 0.21 | H18: =tax.rate -> 0.21 | I18: =tax.rate -> 0.21 | J18: =tax.rate -> 0.21 | K18: =tax.rate -> 0.21
C19: EBIAT (NOPAT - Net Op Profit After Tax) | G19: {=_xlfn.ANCHORARRAY(G17)*(1-G18:K18)} -> 2860.1666 | H19: 2970.6466 | I19: 3156.4563 | J19: 3445.3977 | K19: 3652.797
D20: Add back: Depr & Amort | G20: {=-_xlfn.ANCHORARRAY(G16)} -> 3841.0598 | H20: 3841.0598 | I20: 3841.0598 | J20: 3841.0598 | K20: 3841.0598
D21: Working Capital Change | G21: =SUM('Financial Statements'!K96:K100) -> 552.35495 | H21: =SUM('Financial Statements'!L96:L100) -> 521.32054 | I21: =SUM('Financial Statements'!M96:M100) -> 366.14857 | J21: =SUM('Financial Statements'!N96:N100) -> 188.0239 | K21: =SUM('Financial Statements'!O96:O100) -> -89.119715
C22: Unlevered Cash From Operations | G22: =SUM(G19:G21) -> 7253.5814 | H22: =SUM(H19:H21) -> 7333.0269 | I22: =SUM(I19:I21) -> 7363.6647 | J22: =SUM(J19:J21) -> 7474.4814 | K22: =SUM(K19:K21) -> 7404.7371
D23: Less: CAPEX | G23: {=-P.F.CAPEX} -> -1750 | H23: -1750 | I23: -1750 | J23: -1750 | K23: -1750
C24: Unlevered Free Cash Flow | G24: {=+G22:K22+_xlfn.ANCHORARRAY(G23)} -> 5503.5814 | H24: 5583.0269 | I24: 5613.6647 | J24: 5724.4814 | K24: 5654.7371
D25: Discount Factor | G25: =1/(1+WACC)^G100 -> 0.88150755 | H25: =1/(1+WACC)^H100 -> 0.77705556 | I25: =1/(1+WACC)^I100 -> 0.68498034 | J25: =1/(1+WACC)^J100 -> 0.60381535 | K25: =1/(1+WACC)^K100 -> 0.53226779
C26: Discounted Free Cash Flow | G26: {=+_xlfn.ANCHORARRAY(G24)*G25:K25} -> 4851.4486 | H26: 4338.3221 | I26: 3845.25 | J26: 3456.5297 | K26: 3009.8344
C28: Net Present Value of the DCF | G28: =SUM(_xlfn.ANCHORARRAY(G26)) -> 19501.385
B30: Enterprise Valuations
C31: Perpetuity Approach
D32: Unlevered FCF Year 5 | G32: =DCF.Terminal.Free.Cash.Flow -> 5654.7371
D33: Long Term Growth Rate | G33: 0.04
D34: Forecast Year 6 FCF | G34: =+G32*(1+G33) -> 5880.9266
C35: Terminal Value | G35: =+G34/(WACC-G33) -> 62284.602
C36: NPV Calculation
D37: PV of the Terminal Value | G37: =+G35*DCF.Terminal.Discount.Factor -> 33152.087
D38: PV of the Free Cash Flows | G38: =+DCF.NPV.DCF -> 19501.385
C39: Total Enterprise Value | G39: =SUM(G37:G38) -> 52653.472
D40: Implied Term Value Exit Multiplier | G40: =G39/DCF.Terminal.EBITDA -> 6.2202461
C42: Exit EBITDA Multiple Approach
C43: Terminal Value Calculation
D44: EBITDA Year 5 | G44: =DCF.Terminal.EBITDA -> 8464.8535
D45: Expected Exit Multiplier | G45: 8
...

Sheet DebtSchedule
A1: =company.name&" Debt Schedule" -> Legends Inc. Debt Schedule
G2: {=dates.hist} -> 2022 | H2: 2023 | I2: 2024 | J2: LBO | K2: {=+dates.forecast} -> 2025 | L2: 2026 | M2: 2027 | N2: 2028 | O2: 2029
B3: Debt
C4: Huntington | G4: 2000 | H4: 1750 | I4: 1500 | J4: 0 | K4: =+J4 -> 0 | L4: =+K4 -> 0 | M4: =+L4 -> 0 | N4: =+M4 -> 0 | O4: =+N4 -> 0 | P4: =+O4 -> 0
C5: PNC | G5: 2500 | H5: =+G5 -> 2500 | I5: =+H5 -> 2500 | J5: 0 | K5: =+J5 -> 0 | L5: =+K5 -> 0 | M5: =+L5 -> 0 | N5: =+M5 -> 0 | O5: =+N5 -> 0 | P5: =+O5 -> 0
C6: Keybank | G6: 3500 | H6: 3500 | I6: 1500 | J6: 0 | K6: =+J6 -> 0 | L6: =+K6 -> 0 | M6: =+L6 -> 0 | N6: =+M6 -> 0 | O6: =+N6 -> 0 | P6: =+O6 -> 0
C7: LBO Revolver | G7: 0 | H7: 0 | I7: 0 | J7: =+LBO.Revolver -> 20000 | K7: =+J7+K26+K27 -> 18500 | L7: =+K7+L26+L27 -> 16603.763 | M7: =+L7+M26+M27 -> 14303.886 | N7: =+M7+N26+N27 -> 11645.471 | O7: =+N7+O26+O27 -> 8713.3719 | P7: =+O7+P26+P27 -> 7213.3719
C8: Subordinated Debt | G8: 0 | H8: 0 | I8: 0 | J8: =+LBO.SubDebt -> 20000 | K8: =+J8 -> 20000 | L8: =+K8 -> 20000 | M8: =+L8 -> 20000 | N8: =+M8 -> 20000 | O8: =+N8 -> 20000 | P8: =+O8 -> 20000
B9: Total Debt | G9: =SUM(G4:G8) -> 8000 | H9: =SUM(H4:H8) -> 7750 | I9: =SUM(I4:I8) -> 5500 | J9: =SUM(J4:J8) -> 40000 | K9: =SUM(K4:K8) -> 38500 | L9: =SUM(L4:L8) -> 36603.763 | M9: =SUM(M4:M8) -> 34303.886 | N9: =SUM(N4:N8) -> 31645.471 | ... P9: =SUM(P4:P8) -> 27213.372
I10: DCF.Debt
B11: Interest Rate
C12: {=+C4:C8} -> Huntington | G12: 0.0645 | H12: =+G12 -> 0.0645 | I12: =+H12 -> 0.0645 | K12: =+I12 -> 0.0645 | L12: =+K12 -> 0.0645 | M12: =+L12 -> 0.0645 | N12: =+M12 -> 0.0645 | O12: =+N12 -> 0.0645
C13: PNC | G13: 0.0725 | H13: =+G13 -> 0.0725 | I13: =+H13 -> 0.0725 | K13: =+I13 -> 0.0725 | L13: =+K13 -> 0.0725 | M13: =+L13 -> 0.0725 | N13: =+M13 -> 0.0725 | O13: =+N13 -> 0.0725
C14: Keybank | G14: 0.0615 | H14: =+G14 -> 0.0615 | I14: =+H14 -> 0.0615 | K14: =+I14 -> 0.0615 | L14: =+K14 -> 0.0615 | M14: =+L14 -> 0.0615 | N14: =+M14 -> 0.0615 | O14: =+N14 -> 0.0615
C15: LBO Revolver | G15: 0 | H15: =+G15 -> 0 | I15: =+H15 -> 0 | K15: 0.075 | L15: =+K15 -> 0.075 | M15: =+L15 -> 0.075 | N15: =+M15 -> 0.075 | O15: =+N15 -> 0.075
C16: Subordinated Debt | G16: 0 | H16: =+G16 -> 0 | I16: =+H16 -> 0 | K16: 0.105 | L16: =+K16 -> 0.105 | M16: =+L16 -> 0.105 | N16: =+M16 -> 0.105 | O16: =+N16 -> 0.105
B18: Interest Expense | G18: =SUMPRODUCT(G4:G8,G12:G16) -> 525.5 | H18: =SUMPRODUCT(H4:H8,H12:H16) -> 509.375 | I18: =SUMPRODUCT(I4:I8,I12:I16) -> 370.25 | K18: =SUMPRODUCT(K4:K8,K12:K16) -> 3487.5 | L18: =SUMPRODUCT(L4:L8,L12:L16) -> 3345.2822 | M18: =SUMPRODUCT(M4:M8,M12:M16) -> 3172.7914 | N18: =SUMPRODUCT(N4:N8,N12:N16) -> 2973.4103 | O18: =SUMPRODUCT(O4:O8,O12:O16) -> 2753.5029
B20: Calculate Current Portion of Long Term Debt
C21: Current Portion | G21: =+G9-H9 -> 250 | H21: =+H9-I9 -> 2250 | I21: =+J9-K9 -> 1500 | J21: =+J9-K9 -> 1500 | K21: =+K9-L9 -> 1896.2368 | L21: =+L9-M9 -> 2299.8777 | M21: =+M9-N9 -> 2658.4142 | N21: =+N9-O9 -> 2932.0994 | O21: =+O9-P9 -> 1500
C22: Long Term Debt | G22: =+G9-G21 -> 7750 | H22: =+H9-H21 -> 5500 | I22: =+I9-I21 -> 4000 | J22: =+J9-J21 -> 38500 | K22: =+K9-K21 -> 36603.763 | L22: =+L9-L21 -> 34303.886 | M22: =+M9-M21 -> 31645.471 | N22: =+N9-N21 -> 28713.372 | O22: =+O9-O21 -> 27213.372
B24: Revolver Paydown
C25: Paydown Amounts
D26: Mandatory | K26: -1500 | L26: =+K26 -> -1500 | M26: =+L26 -> -1500 | N26: =+M26 -> -1500 | O26: =+N26 -> -1500 | P26: =+O26 -> -1500
D27: Variable | K27: {=+K44:O44} -> 0 | L27: -396.23678 | M27: -799.87768 | N27: -1158.4142 | O27: -1432.0994
C28: Revolver Discretionary Paydown Calculation
D29: Levered Free Cash Flow
E30: Net income | K30: {=+F.Net.Income} -> 105.04164 | L30: 327.87361 | M30: 649.95113 | N30: 1096.4035 | O30: 1477.5297
E31: Add Back:
F32: Depreciation | K32: {=P.F.Depreciation.Expense} -> 1000 | L32: 1000 | M32: 1000 | N32: 1000 | O32: 1000
F33: Amortization | K33: {=P.F.Amortization.Expense} -> 2841.0598 | L33: 2841.0598 | M33: 2841.0598 | N33: 2841.0598 | O33: 2841.0598
F34: Non-Cash Interest (aka: PIK) | K34: 0 | L34: =+K34 -> 0 | M34: =+L34 -> 0 | N34: =+M34 -> 0 | O34: =+N34 -> 0
E35: Change In Working Capital | K35: =+SUM('Financial Statements'!K96:K100) -> 552.35495 | L35: =+SUM('Financial Statements'!L96:L100) -> 521.32054 | M35: =+SUM('Financial Statements'!M96:M100) -> 366.14857 | N35: =+SUM('Financial Statements'!N96:N100) -> 188.0239 | O35: =+SUM('Financial Statements'!O96:O100) -> -89.119715
E36: CAPEX | K36: {=-P.F.CAPEX} -> -1750 | L36: -1750 | M36: -1750 | N36: -1750 | O36: -1750
D37: Net Levered Free Cash Flow | K37: =SUM(K26:K36) -> 1248.4564 | L37: =SUM(L26:L36) -> 1044.0172 | M37: =SUM(M26:M36) -> 807.28181 | N37: =SUM(N26:N36) -> 717.07304 | O37: =SUM(O26:O36) -> 547.3704
B38: Beginning Cash Balance | K38: {=F.STarting.Cash} -> 5000 | L38: 6248.4564 | M38: 7292.4736 | N38: 8099.7554 | O38: 8816.8284
C39: Less: Minimum Cash Balance | K39: =-minimum.cash.balance -> -5000 | L39: =-minimum.cash.balance -> -5000 | M39: =-minimum.cash.balance -> -5000 | N39: =-minimum.cash.balance -> -5000 | O39: =-minimum.cash.balance -> -5000
C40: Plus: Levered Free Cash Flow | K40: {=+K37:O37} -> 1248.4564 | L40: 1044.0172 | M40: 807.28181 | N40: 717.07304 | O40: 547.3704
D41: LFCF Before Scheduled Paydown | K41: =SUM(K38:K40) -> 1248.4564 | L41: =SUM(L38:L40) -> 2292.4736 | M41: =SUM(M38:M40) -> 3099.7554 | N41: =SUM(N38:N40) -> 3816.8284 | O41: =SUM(O38:O40) -> 4364.1988
E42: Less: Scheduled Revolver Paydown | K42: {=+K26:O26} -> -1500 | L42: -1500 | M42: -1500 | N42: -1500 | O42: -1500
D43: LFCF After Paydown | K43: =SUM(K41:K42) -> -251.54361 | L43: =SUM(L41:L42) -> 792.47356 | M43: =SUM(M41:M42) -> 1599.7554 | N43: =SUM(N41:N42) -> 2316.8284 | O43: =SUM(O41:O42) -> 2864.1988
...
