Workbook
Name Acq.Costs.PCT: 'Property Summary'!$G$5
Name Amort.Period: 'Property Summary'!$G$27
Name Analysis.Period: 'Property Summary'!$D$7
Name Basis: 'Property Summary'!$G$6
Name Debt.Service: Debt!$E$5:$O$5
Name Discount.Rate: 'Property Summary'!$D$11
Name Estimated.Gross.Revenue: 'Cash Flow'!$E$14
Name Forecast.CapEx: Forecast.CAPEX!$E$22
Name Forecast.Free.Rent: 'Forecast.Free Rent'!$E$22
Name Forecast.OpEx: Expenses!$F$13:$P$13
Name Forecast.ReLeasing.Cost: Forecast.ReLeasing!$E$22
Name Forecast.Vacancy: Forecast.Vacancy!$E$22
Name Forecast.Value.Add.Costs: Expenses!$F$16:$P$16
Name Infl.CapEx: 'Property Summary'!$J$20
Name Infl.Operating.Expenses: 'Property Summary'!$J$19
Name Infl.Other.Income: 'Property Summary'!$J$18
Name Infl.ReLeasing.Costs: 'Property Summary'!$J$21
Name Infl.Rent: 'Property Summary'!$J$17
Name Initial.Equity: 'Property Summary'!$G$22
Name Interest.Expense: Debt!$E$6:$O$6
Name Interest.Rate: 'Property Summary'!$G$25
Name IRR.Unlevered: 'Property Returns'!$D$51:$N$51
Name Lender.Fee.AMT: 'Property Summary'!$G$21
Name Lender.Fee.PCT: 'Property Summary'!$G$20
Name Loan.Amount: 'Property Summary'!$G$17
Name Loan.Balance: Debt!$E$7:$O$7
Name Locale: 'Property Summary'!$D$4
Name Market.Cap.Rate: 'Property Summary'!$D$10
Name Monthly.Forecast.Unit: 'Forecast. Monthly Rent'!$F$22
Name Monthly.Revenue.Forecast: 'Forecast. Monthly Rent'!$E$22
Name Monthly.Revenue.Year: 'Forecast. Monthly Rent'!$C$22
Name Net.Operating.Income: 'Cash Flow'!$E$27
Name Num.Apartments: 'Property Summary'!$G$3
Name Occupancy: 'Property Summary'!$D$5
Name Operating.Expenses: 'Cash Flow'!$E$25
Name Other.Income: 'Property Summary'!$G$13
Name PIK.Period: 'Property Summary'!$G$26
Name Potential.Gross.Income: 'Cash Flow'!$E$7
Name Price.Per.Unit: 'Property Summary'!$G$8
Name Property: 'Property Summary'!$D$3
Name Purchase.Price: 'Property Summary'!$D$13
Name rent.roll.assumptions: 'Rent Roll'!$B$3:$Q$8
Name Sales.Price.Forecast: 'Property Returns'!$C$12
Name Start.Date: 'Property Summary'!$D$6
Name Term: 'Property Summary'!$G$28
Name Term.Cap.Growth.BPS: 'Property Summary'!$D$9
Name Term.Cap.Year: 'Property Summary'!$D$8
Name Timeline: Expenses!$F$4
Name Total.CapEx: 'Cash Flow'!$E$33:$O$33
Name Total.Equity.Required: 'Property Summary'!$G$23
Name Total.Equity.Requirement: 'Property Summary'!$G$23
Name Unit.Replacement.Cost: 'Property Summary'!$D$12
Name Upfront.CAPEX: 'Property Summary'!$G$4
Name Vacancy.Rate: 'Property Summary'!$G$14

Sheet Property Summary
B2: Property Summary
B3: Property Name | D3: Flashewoode Heights | F3: Apartments | G3: 124
B4: City, State | D4: Kent, OH | F4: Upfront CapEx | G4: 250000
B5: Current Occupancy | D5: 0.93 | F5: Acquisition Costs | G5: 0.01
B6: Analysis Start | D6: 45809 | F6: All-In Basis | G6: =(Purchase.Price*(1+Acq.Costs.PCT))+Upfront.CAPEX+Lender.Fee.AMT -> 7619625
B7: Analaysis Period | D7: 10 | F7: Going-In Cap Rate | G7: tbd
B8: Terminal Cap Year | D8: 11 | F8: Price/Unit | G8: =Basis/Num.Apartments -> 61448.589
B9: Terminal Cap Growth/Year | D9: 10 | F9: Year 1 Net Operating Income (aka NOI) | G9: tbd
B10: Market Cap Rate | D10: 0.065 | F10: Year 3 NOI | G10: tbd
B11: Discount Rate | D11: 0.075 | F11: Terminal Cap Rate | G11: tbd
B12: Replacement Cost | D12: 60000 | F12: Terminal Value | G12: tbd
B13: Set Purchase Price | D13: 7250000 | F13: Other Income/Year | G13: 50000
F14: General Vacancy | G14: 0.08
B16: Property Metrics | F16: Financing Assumptions | I16: Inflation Assumptions
B17: Purchase Price | D17: =+Purchase.Price -> 7250000 | F17: Loan Amount | G17: 4712500 | I17: Rent | J17: 0.035
B18: Replacement Cost | D18: =+Unit.Replacement.Cost*Num.Apartments -> 7440000 | F18: Loan To Value (LTV) | G18: =G17/Purchase.Price -> 0.65 | I18: Other Income | J18: 0.01
F19: Loan to Cost (LTC) | I19: Operating Expenses | J19: 0.025
B20: Unlevered IRR | D20: tbd | F20: Lender Fee % | G20: 0.01 | I20: CapEx | J20: 0.035
B21: Unlevered Equity Multiple | D21: tbd | F21: Lender Fees | G21: =Loan.Amount*Lender.Fee.PCT -> 47125 | I21: Re-Leasing Costs | J21: 0.02
B22: Average Free and Clear Returns | D22: tbd | F22: Initial Equity Required | G22: =Basis-Loan.Amount -> 2907125
F23: Total Equity Required | G23: tbd
B24: Levered IRR | D24: tbd
B25: Levered Equity Multiple | D25: tbd | F25: Interest Rate | G25: 0.07
B26: Averae Cash on Cash Returns | D26: tbd | F26: Years Interest-Only (PIK) | G26: 2
F27: Amortization Period | G27: 28
B28: Minimum DSCR (NOI) | D28: tbd | F28: Term | G28: 30
B29: Minimum Debt Yield (NOI) | D29: tbd

Sheet Property Returns
B2: Property Returns Analysis
C3: {=+_xlfn.ANCHORARRAY(Timeline)} -> 1 | D3: 2 | E3: 3 | F3: 4 | G3: 5 | H3: 6 | I3: 7 | J3: 8 | K3: 9 | L3: 10 | M3: 11
C4: {=EOMONTH(Start.Date-1,(_xlfn.ANCHORARRAY(C3))*12)} -> 46173 | D4: 46538 | E4: 46904 | F4: 47269 | G4: 47634 | H4: 47999 | I4: 48365 | J4: 48730 | K4: 49095 | L4: 49460 | M4: 49826
B5: Estimated Gross Revenue | C5: {=+_xlfn.ANCHORARRAY(Estimated.Gross.Revenue)} -> 1100936 | D5: 1236783.9 | E5: 1356245.5 | F5: 1402439 | G5: 1450236.5 | H5: 1499694 | I5: 1550869.5 | J5: 1603823.1 | K5: 1658616.7 | L5: 1715314.7 | M5: 1773983.6
B6: Less: Operating Expenses (OpEx) | C6: {=-_xlfn.ANCHORARRAY(Operating.Expenses)} -> -625128.08 | D6: -644006.02 | E6: -662762.43 | F6: -679700.11 | G6: -697074.71 | H6: -714897.62 | I6: -733180.56 | J6: -751935.53 | K6: -771174.86 | L6: -790911.21 | M6: -811157.57
B7: Net Operating Income | C7: {=+_xlfn.ANCHORARRAY(C5)+_xlfn.ANCHORARRAY(C6)} -> 475807.92 | D7: 592777.86 | E7: 693483.1 | F7: 722738.89 | G7: 753161.78 | H7: 784796.38 | I7: 817688.98 | J7: 851887.54 | K7: 887441.85 | L7: 924403.51 | M7: 962826.06
B8: Less: Capital Expenditures (CapEx) | C8: {=-Total.CapEx} -> -451760 | D8: -355073.2 | E8: -108497.39 | F8: -112036.37 | G8: -115694.04 | H8: -119474.45 | I8: -123381.8 | J8: -127420.43 | K8: -131594.81 | L8: -135909.59 | M8: -140369.56
B9: Cash From Operations | C9: {=+_xlfn.ANCHORARRAY(C7)+_xlfn.ANCHORARRAY(C8)} -> 24047.92 | D9: 237704.66 | E9: 584985.71 | F9: 610702.52 | G9: 637467.74 | H9: 665321.93 | I9: 694307.17 | J9: 724467.11 | K9: 755847.04 | L9: 788493.93 | M9: 822456.5
B11: Cap Rate @ Forecast Year End | C11: {=Market.Cap.Rate+(Term.Cap.Growth.BPS/10000)*(_xlfn.ANCHORARRAY(C3))} -> 0.066 | D11: 0.067 | E11: 0.068 | F11: 0.069 | G11: 0.07 | H11: 0.071 | I11: 0.072 | J11: 0.073 | K11: 0.074 | L11: 0.075 | M11: 0.076
B12: Net Sales Price @ Forecast Year End | C12: {=+_xlfn.ANCHORARRAY(C7)/_xlfn.ANCHORARRAY(C11)} -> 7209210.9 | D12: 8847430.8 | E12: 10198281 | F12: 10474477 | G12: 10759454 | H12: 11053470 | I12: 11356791 | J12: 11669692 | K12: 11992457 | L12: 12325380 | M12: 12668764
B13: Net Sales Price / Unit | C13: {=_xlfn.ANCHORARRAY(C12)/Num.Apartments} -> 58138.798 | D13: 71350.248 | E13: 82244.201 | F13: 84471.586 | G13: 86769.79 | H13: 89140.889 | I13: 91587.027 | J13: 94110.422 | K13: 96713.366 | L13: 99398.227 | M13: 102167.45
B15: Cash From Operations | C15: {=+_xlfn.ANCHORARRAY(C9)} -> 24047.92 | D15: 237704.66 | E15: 584985.71 | F15: 610702.52 | G15: 637467.74 | H15: 665321.93 | I15: 694307.17 | J15: 724467.11 | K15: 755847.04 | L15: 788493.93 | M15: 822456.5
B16: Free and Clear Returns | C16: {=_xlfn.ANCHORARRAY(C15)/Purchase.Price} -> 0.0033169545 | D16: 0.03278685 | E16: 0.080687684 | F16: 0.08423483 | G16: 0.087926585 | H16: 0.091768543 | I16: 0.095766507 | J16: 0.099926499 | K16: 0.10425476 | L16: 0.10875778 | M16: 0.11344228
B17: Rolling Average Free and Clear Returns | C17: =AVERAGE($C16:C16) -> 0.0033169545 | D17: =AVERAGE($C16:D16) -> 0.018051902 | E17: =AVERAGE($C16:E16) -> 0.038930496 | F17: =AVERAGE($C16:F16) -> 0.05025658 | G17: =AVERAGE($C16:G16) -> 0.057790581 | H17: =AVERAGE($C16:H16) -> 0.063453574 | I17: =AVERAGE($C16:I16) -> 0.068069708 | J17: =AVERAGE($C16:J16) -> 0.072051806 | ... M17: =AVERAGE($C16:M16) -> 0.082079025
B18: Unlevered Cash Flow With Residual | C18: {=+IF(_xlfn.ANCHORARRAY(C3)<=Analysis.Period,_xlfn.ANCHORARRAY(C15),0)+IF(_xlfn.ANCHORARRAY(C3)=Analysis.Period,_xlfn.ANCHORARRAY(C12),0)} -> 24047.92 | D18: 237704.66 | E18: 584985.71 | F18: 610702.52 | G18: 637467.74 | H18: 665321.93 | I18: 694307.17 | J18: 724467.11 | K18: 755847.04 | L18: 13113874 | M18: 0
B20: Unlevered IRR | C20: {=IRR.Unlevered} -> -0.002309127 | D20: 0.12108908 | E20: 0.15217651 | F20: 0.13642908 | G20: 0.12746737 | H20: 0.12178139 | I20: 0.11792198 | J20: 0.11518218 | K20: 0.11317607 | L20: 0.11167513
B21: Unlevered Equity Multiple | C21: =IF(C3<=Analysis.Period,SUM(D53:D62)/Purchase.Price,"") -> 0.99769087 | D21: =IF(D3<=Analysis.Period,SUM(E53:E62)/Purchase.Price,"") -> 1.2564391 | E21: =IF(E3<=Analysis.Period,SUM(F53:F62)/Purchase.Price,"") -> 1.5234509 | F21: =IF(F3<=Analysis.Period,SUM(G53:G62)/Purchase.Price,"") -> 1.6457817 | G21: =IF(G3<=Analysis.Period,SUM(H53:H62)/Purchase.Price,"") -> 1.7730155 | H21: =IF(H3<=Analysis.Period,SUM(I53:I62)/Purchase.Price,"") -> 1.905338 | I21: =IF(I3<=Analysis.Period,SUM(J53:J62)/Purchase.Price,"") -> 2.0429419 | J21: =IF(J3<=Analysis.Period,SUM(K53:K62)/Purchase.Price,"") -> 2.1860272 | ... M21: =IF(M3<=Analysis.Period,SUM(N53:N62)/Purchase.Price,"")
B23: Portion of IRR From Income | C23: =+C17/C20 -> -1.4364539 | D23: =+D17/D20 -> 0.14907952 | E23: =+E17/E20 -> 0.25582461 | F23: =+F17/F20 -> 0.36837145 | G23: =+G17/G20 -> 0.4533755 | H23: =+H17/H20 -> 0.52104492 | I23: =+I17/I20 -> 0.57724358 | J23: =+J17/J20 -> 0.62554645 | ... L23: =+L17/L20 -> 0.70689599
B24: Portion of IRR From Sale | C24: =100%-C23 -> 2.4364539 | D24: =100%-D23 -> 0.85092048 | E24: =100%-E23 -> 0.74417539 | F24: =100%-F23 -> 0.63162855 | G24: =100%-G23 -> 0.5466245 | H24: =100%-H23 -> 0.47895508 | I24: =100%-I23 -> 0.42275642 | J24: =100%-J23 -> 0.37445355 | ... L24: =100%-L23 -> 0.29310401
B26: Leverage Analysis
B27: Debt Service | C27: {=Debt.Service} -> 0 | D27: 0 | E27: -78561.714 | F27: -84061.034 | G27: -89945.307 | H27: -96241.478 | I27: -102978.38 | J27: -110186.87 | K27: -117899.95 | L27: -126152.95 | M27: -134983.65
B28: Debt Service Coverage Ratio | C28: =IF(C27<0,C7/-C27,0) -> 0 | D28: =IF(D27<0,D7/-D27,0) -> 0 | E28: =IF(E27<0,E7/-E27,0) -> 8.8272399 | F28: =IF(F27<0,F7/-F27,0) -> 8.5977872 | G28: =IF(G27<0,G7/-G27,0) -> 8.3735528 | H28: =IF(H27<0,H7/-H27,0) -> 8.1544506 | I28: =IF(I27<0,I7/-I27,0) -> 7.9403945 | J28: =IF(J27<0,J7/-J27,0) -> 7.7312982 | ... M28: =IF(M27<0,M7/-M27,0) -> 7.1329087
B29: Debt Yield (Net Op Income)
B50: Unlevered | D50: {=+_xlfn.ANCHORARRAY(Timeline)} -> 1 | E50: 2 | F50: 3 | G50: 4 | H50: 5 | I50: 6 | J50: 7 | K50: 8 | L50: 9 | M50: 10 | N50: 11
C51: Forecast IRR | D51: =IF(D50<=Analysis.Period,IRR(D52:D62),"") -> -0.002309127 | E51: =IF(E50<=Analysis.Period,IRR(E52:E62),"") -> 0.12108908 | F51: =IF(F50<=Analysis.Period,IRR(F52:F62),"") -> 0.15217651 | G51: =IF(G50<=Analysis.Period,IRR(G52:G62),"") -> 0.13642908 | H51: =IF(H50<=Analysis.Period,IRR(H52:H62),"") -> 0.12746737 | I51: =IF(I50<=Analysis.Period,IRR(I52:I62),"") -> 0.12178139 | J51: =IF(J50<=Analysis.Period,IRR(J52:J62),"") -> 0.11792198 | K51: =IF(K50<=Analysis.Period,IRR(K52:K62),"") -> 0.11518218 | ... N51: =IF(N50<=Analysis.Period,IRR(N52:N62),"")
B52: Analysis Period | C52: 0 | D52: {=-Purchase.Price*_xlfn.ANCHORARRAY(D50)/_xlfn.ANCHORARRAY(D50)} -> -7250000 | E52: -7250000 | F52: -7250000 | G52: -7250000 | H52: -7250000 | I52: -7250000 | J52: -7250000 | K52: -7250000 | L52: -7250000 | M52: -7250000 | N52: -7250000
C53: {=_xlfn.SEQUENCE(Analysis.Period,1,1,1)} -> 1 | D53: {=INDEX(_xlfn.ANCHORARRAY(Sales.Price.Forecast),1,_xlfn.ANCHORARRAY(C53))*IF(_xlfn.ANCHORARRAY(C53)=_xlfn.ANCHORARRAY(D50),1,0)+INDEX(_xlfn.ANCHORARRAY(C9),1,_xlfn.ANCHORARRAY(C53))*IF(_xlfn.ANCHORARRAY(C53)<=_xlfn.ANCHORARRAY(D50),1,0)} -> 7233258.8 | E53: 24047.92 | F53: 24047.92 | G53: 24047.92 | H53: 24047.92 | I53: 24047.92 | J53: 24047.92 | K53: 24047.92 | L53: 24047.92 | M53: 24047.92 | N53: 24047.92
C54: 2 | D54: 0 | E54: 9085135.5 | F54: 237704.66 | G54: 237704.66 | H54: 237704.66 | I54: 237704.66 | J54: 237704.66 | K54: 237704.66 | L54: 237704.66 | M54: 237704.66 | N54: 237704.66
C55: 3 | D55: 0 | E55: 0 | F55: 10783267 | G55: 584985.71 | H55: 584985.71 | I55: 584985.71 | J55: 584985.71 | K55: 584985.71 | L55: 584985.71 | M55: 584985.71 | N55: 584985.71
C56: 4 | D56: 0 | E56: 0 | F56: 0 | G56: 11085179 | H56: 610702.52 | I56: 610702.52 | J56: 610702.52 | K56: 610702.52 | L56: 610702.52 | M56: 610702.52 | N56: 610702.52
C57: 5 | D57: 0 | E57: 0 | F57: 0 | G57: 0 | H57: 11396922 | I57: 637467.74 | J57: 637467.74 | K57: 637467.74 | L57: 637467.74 | M57: 637467.74 | N57: 637467.74
C58: 6 | D58: 0 | E58: 0 | F58: 0 | G58: 0 | H58: 0 | I58: 11718792 | J58: 665321.93 | K58: 665321.93 | L58: 665321.93 | M58: 665321.93 | N58: 665321.93
C59: 7 | D59: 0 | E59: 0 | F59: 0 | G59: 0 | H59: 0 | I59: 0 | J59: 12051099 | K59: 694307.17 | L59: 694307.17 | M59: 694307.17 | N59: 694307.17
C60: 8 | D60: 0 | E60: 0 | F60: 0 | G60: 0 | H60: 0 | I60: 0 | J60: 0 | K60: 12394159 | L60: 724467.11 | M60: 724467.11 | N60: 724467.11
C61: 9 | D61: 0 | E61: 0 | F61: 0 | G61: 0 | H61: 0 | I61: 0 | J61: 0 | K61: 0 | L61: 12748304 | M61: 755847.04 | N61: 755847.04
C62: 10 | D62: 0 | E62: 0 | F62: 0 | G62: 0 | H62: 0 | I62: 0 | J62: 0 | K62: 0 | L62: 0 | M62: 13113874 | N62: 788493.93
B64: Levered | D64: {=+_xlfn.ANCHORARRAY(Timeline)} -> 1 | E64: 2 | F64: 3 | G64: 4 | H64: 5 | I64: 6 | J64: 7 | K64: 8 | L64: 9 | M64: 10 | N64: 11
C65: Forecast IRR | D65: =IF(D64<=Analysis.Period,IRR(D66:D76),"") -> 1.4798416 | E65: =IF(E64<=Analysis.Period,IRR(E66:E76),"") -> 0.74452291 | F65: =IF(F64<=Analysis.Period,IRR(F66:F76),"") -> 0.51945455 | G65: =IF(G64<=Analysis.Period,IRR(G66:G76),"") -> 0.37773956 | H65: =IF(H64<=Analysis.Period,IRR(H66:H76),"") -> 0.29916791 | I65: =IF(I64<=Analysis.Period,IRR(I66:I76),"") -> 0.24931651 | J65: =IF(J64<=Analysis.Period,IRR(J66:J76),"") -> 0.21490327 | K65: =IF(K64<=Analysis.Period,IRR(K66:K76),"") -> 0.18973287 | ... N65: =IF(N64<=Analysis.Period,IRR(N66:N76),"")
B66: Analysis Period | C66: 0 | D66: {=-Initial.Equity*_xlfn.ANCHORARRAY(D64)/_xlfn.ANCHORARRAY(D64)} -> -2907125 | E66: -2907125 | F66: -2907125 | G66: -2907125 | H66: -2907125 | I66: -2907125 | J66: -2907125 | K66: -2907125 | L66: -2907125 | M66: -2907125 | N66: -2907125
C67: {=_xlfn.SEQUENCE(Analysis.Period,1,1,1)} -> 1 | D67: {=INDEX(_xlfn.ANCHORARRAY(Sales.Price.Forecast),1,_xlfn.ANCHORARRAY(C67))*IF(_xlfn.ANCHORARRAY(C67)=_xlfn.ANCHORARRAY(D64),1,0)+INDEX(C23:L23,1,_xlfn.ANCHORARRAY(C67))*IF(_xlfn.ANCHORARRAY(C67)<=_xlfn.ANCHORARRAY(D64),1,0)} -> 7209209.5 | E67: -1.4364539 | F67: -1.4364539 | G67: -1.4364539 | H67: -1.4364539 | I67: -1.4364539 | J67: -1.4364539 | K67: -1.4364539 | L67: -1.4364539 | M67: -1.4364539 | N67: -1.4364539
...

Sheet Rent Roll
B2: Multifamily Rent Roll | E2: Residential Units | G2: =Num.Apartments -> 124
B3: Unit Name | C3: # of Units | D3: Bedrooms | E3: Baths | F3: Rentable Area | G3: In-Place Rent/Mo | H3: Market Rent/Mo | I3: Months to roll to market | J3: Lease Term | K3: CapEx/Unit | L3: Free Rent Per New Lease | M3: Vacancy Between Leases | N3: Re-Leasing Costs | O3: Renewal Probability | P3: Days Vacant | Q3: Blended Releasing Cost
B4: Studio | C4: 40 | D4: 0 | E4: 1 | F4: 430 | G4: 510 | H4: 630 | I4: 12 | J4: 12 | K4: 50 | L4: 1 | M4: 20 | N4: 300 | O4: 0.6 | P4: 8 | Q4: =+(1-O4)*N4 -> 120
B5: 1bd/1ba | C5: 24 | D5: 1 | E5: 1 | F5: 671 | G5: 660 | H5: 780 | I5: 16 | J5: 12 | K5: 50 | L5: 1 | M5: 20 | N5: 300 | O5: =+O4 -> 0.6 | P5: 8 | Q5: =+(1-O5)*N5 -> 120
B6: 2bd/2ba | C6: 24 | D6: 2 | E6: 2 | F6: 945 | G6: 850 | H6: 970 | I6: 19 | J6: 12 | K6: 60 | L6: 0 | M6: 25 | N6: 350 | O6: =+O5 -> 0.6 | P6: 10 | Q6: =+(1-O6)*N6 -> 140
B7: 2bd/1.5ba | C7: 12 | D7: 2 | E7: 1.5 | F7: 1025 | G7: 850 | H7: 970 | I7: 22 | J7: 12 | K7: 65 | L7: 0 | M7: 25 | N7: 350 | O7: =+O6 -> 0.6 | P7: 10 | Q7: =+(1-O7)*N7 -> 140
B8: 3bd/2ba | C8: 24 | D8: 3 | E8: 2 | F8: 1046 | G8: 1100 | H8: 1220 | I8: 25 | J8: 12 | K8: 70 | L8: 0 | M8: 30 | N8: 400 | O8: =+O7 -> 0.6 | P8: 12 | Q8: =+(1-O8)*N8 -> 160

Sheet Expenses
B2: Operating Expense Assumptions (aka OpEx)
B4: Growth Rate | C4: Expense | E4: Initial Year | F4: {=_xlfn.SEQUENCE(1,Term.Cap.Year,1,1)} -> 1 | G4: 2 | H4: 3 | I4: 4 | J4: 5 | K4: 6 | L4: 7 | M4: 8 | N4: 9 | O4: 10 | P4: 11
B5: 0.025 | C5: Marketing | E5: 250 | F5: {=($E5*Num.Apartments)*(1+$B5)^(_xlfn.ANCHORARRAY(Timeline)-1)} -> 31000 | G5: 31775 | H5: 32569.375 | I5: 33383.609 | J5: 34218.2 | K5: 35073.655 | L5: 35950.496 | M5: 36849.258 | N5: 37770.49 | O5: 38714.752 | P5: 39682.621
B6: 0.025 | C6: Administrative | E6: 250 | F6: {=($E6*Num.Apartments)*(1+$B6)^(_xlfn.ANCHORARRAY(Timeline)-1)} -> 31000 | G6: 31775 | H6: 32569.375 | I6: 33383.609 | J6: 34218.2 | K6: 35073.655 | L6: 35950.496 | M6: 36849.258 | N6: 37770.49 | O6: 38714.752 | P6: 39682.621
B7: 0.025 | C7: Utilities | E7: 800 | F7: {=($E7*Num.Apartments)*(1+$B7)^(_xlfn.ANCHORARRAY(Timeline)-1)} -> 99200 | G7: 101680 | H7: 104222 | I7: 106827.55 | J7: 109498.24 | K7: 112235.69 | L7: 115041.59 | M7: 117917.63 | N7: 120865.57 | O7: 123887.21 | P7: 126984.39
B8: 0.025 | C8: Payroll | E8: 1200 | F8: {=($E8*Num.Apartments)*(1+$B8)^(_xlfn.ANCHORARRAY(Timeline)-1)} -> 148800 | G8: 152520 | H8: 156333 | I8: 160241.32 | J8: 164247.36 | K8: 168353.54 | L8: 172562.38 | M8: 176876.44 | N8: 181298.35 | O8: 185830.81 | P8: 190476.58
B9: 0.025 | C9: Repair & Maintenance | E9: 700 | F9: {=($E9*Num.Apartments)*(1+$B9)^(_xlfn.ANCHORARRAY(Timeline)-1)} -> 86800 | G9: 88970 | H9: 91194.25 | I9: 93474.106 | J9: 95810.959 | K9: 98206.233 | L9: 100661.39 | M9: 103177.92 | N9: 105757.37 | O9: 108401.31 | P9: 111111.34
B10: 0.025 | C10: Management (% of Est. Gross Revenue) | D10: 0.03 | F10: {=D10*_xlfn.ANCHORARRAY(Estimated.Gross.Revenue)} -> 33028.08 | G10: 37103.516 | H10: 40687.366 | I10: 42073.17 | J10: 43507.095 | K10: 44990.82 | L10: 46526.086 | M10: 48114.692 | N10: 49758.501 | O10: 51459.442 | P10: 53219.509
B11: 0.025 | C11: Insurance | E11: 225 | F11: {=($E11*Num.Apartments)*(1+$B11)^(_xlfn.ANCHORARRAY(Timeline)-1)} -> 27900 | G11: 28597.5 | H11: 29312.437 | I11: 30045.248 | J11: 30796.38 | K11: 31566.289 | L11: 32355.446 | M11: 33164.333 | N11: 33993.441 | O11: 34843.277 | P11: 35714.359
B12: 0.025 | C12: Taxes | E12: 1350 | F12: {=($E12*Num.Apartments)*(1+$B12)^(_xlfn.ANCHORARRAY(Timeline)-1)} -> 167400 | G12: 171585 | H12: 175874.62 | I12: 180271.49 | J12: 184778.28 | K12: 189397.73 | L12: 194132.68 | M12: 198986 | N12: 203960.65 | O12: 209059.66 | P12: 214286.15
C13: Total Operating Expenses | F13: =SUM(F5:F12) -> 625128.08 | G13: =SUM(G5:G12) -> 644006.02 | H13: =SUM(H5:H12) -> 662762.43 | I13: =SUM(I5:I12) -> 679700.11 | J13: =SUM(J5:J12) -> 697074.71 | K13: =SUM(K5:K12) -> 714897.62 | L13: =SUM(L5:L12) -> 733180.56 | M13: =SUM(M5:M12) -> 751935.53 | ... P13: =SUM(P5:P12) -> 811157.57
C15: Property Renovation / Improvement Costs | F15: 350000 | G15: 250000
C16: Total Value Add Costs | F16: {=+F15:P15} -> 350000 | G16: 250000 | H16: 0 | I16: 0 | J16: 0 | K16: 0 | L16: 0 | M16: 0 | N16: 0 | O16: 0 | P16: 0

Sheet Cash Flow
B2: Multifamily Annual Cash Flow
D3: Ratios | E3: {=+_xlfn.ANCHORARRAY(Timeline)} -> 1 | F3: 2 | G3: 3 | H3: 4 | I3: 5 | J3: 6 | K3: 7 | L3: 8 | M3: 9 | N3: 10 | O3: 11
B4: Potential Gross Income (PGI)
B5: Base Rent | E5: {=SUMIF(_xlfn.ANCHORARRAY(Monthly.Revenue.Year),_xlfn.ANCHORARRAY(E$3),_xlfn.ANCHORARRAY(Monthly.Revenue.Forecast))} -> 1123680 | F5: 1266840 | G5: 1389850.2 | H5: 1438494.9 | I5: 1488842.2 | J5: 1540951.7 | K5: 1594885 | L5: 1650706 | M5: 1708480.7 | N5: 1768277.5 | O5: 1830167.3
B6: Other Income | D6: =AVERAGE(_xlfn.ANCHORARRAY(E6))/AVERAGE(_xlfn.ANCHORARRAY(Potential.Gross.Income)) -> 0.033277203 | E6: {=Other.Income*(1+Infl.Other.Income)^(_xlfn.ANCHORARRAY(E3)-1)} -> 50000 | F6: 50500 | G6: 51005 | H6: 51515.05 | I6: 52030.2 | J6: 52550.503 | K6: 53076.008 | L6: 53606.768 | M6: 54142.835 | N6: 54684.264 | O6: 55231.106
B7: Total PGI | E7: {=_xlfn.ANCHORARRAY(E5)+_xlfn.ANCHORARRAY(E6)} -> 1173680 | F7: 1317340 | G7: 1440855.2 | H7: 1490010 | I7: 1540872.4 | J7: 1593502.2 | K7: 1647961 | L7: 1704312.8 | M7: 1762623.6 | N7: 1822961.8 | O7: 1885398.4
B9: Leasing Costs
B10: Rent Abatement | D10: =AVERAGE(_xlfn.ANCHORARRAY(E10))/AVERAGE(_xlfn.ANCHORARRAY(Potential.Gross.Income)) -> 0.033045583 | E10: {=SUMIF(_xlfn.ANCHORARRAY(Monthly.Revenue.Year),_xlfn.ANCHORARRAY(E$3),Forecast.Free.Rent)} -> 41040 | F10: 45457.2 | G10: 47048.202 | H10: 48694.889 | I10: 50399.21 | J10: 52163.183 | K10: 53988.894 | L10: 55878.505 | M10: 57834.253 | N10: 59858.452 | O10: 61953.498
B11: Vacancy | D11: =AVERAGE(_xlfn.ANCHORARRAY(E11))/AVERAGE(_xlfn.ANCHORARRAY(Potential.Gross.Income)) -> 0.026252656 | E11: {=SUMIF(_xlfn.ANCHORARRAY(Monthly.Revenue.Year),_xlfn.ANCHORARRAY(E$3),Forecast.Vacancy)} -> 31704 | F11: 35098.92 | G11: 37561.433 | H11: 38876.084 | I11: 40236.746 | J11: 41645.033 | K11: 43102.609 | L11: 44611.2 | M11: 46172.592 | N11: 47788.633 | O11: 49461.235
B12: Total Leasing Costs | E12: {=_xlfn.ANCHORARRAY(E10)+_xlfn.ANCHORARRAY(E11)} -> 72744 | F12: 80556.12 | G12: 84609.635 | H12: 87570.973 | I12: 90635.957 | J12: 93808.215 | K12: 97091.503 | L12: 100489.71 | M12: 104006.84 | N12: 107647.08 | O12: 111414.73
B14: Estimated Gross Revenue | E14: {=+_xlfn.ANCHORARRAY(Potential.Gross.Income)-_xlfn.ANCHORARRAY(E12)} -> 1100936 | F14: 1236783.9 | G14: 1356245.5 | H14: 1402439 | I14: 1450236.5 | J14: 1499694 | K14: 1550869.5 | L14: 1603823.1 | M14: 1658616.7 | N14: 1715314.7 | O14: 1773983.6
B16: Operating Expenses (aka OpEx)
B17: Marketing | E17: {=+_xlfn.ANCHORARRAY(Expenses!F5)} -> 31000 | F17: 31775 | G17: 32569.375 | H17: 33383.609 | I17: 34218.2 | J17: 35073.655 | K17: 35950.496 | L17: 36849.258 | M17: 37770.49 | N17: 38714.752 | O17: 39682.621
B18: Administrative | E18: {=+_xlfn.ANCHORARRAY(Expenses!F6)} -> 31000 | F18: 31775 | G18: 32569.375 | H18: 33383.609 | I18: 34218.2 | J18: 35073.655 | K18: 35950.496 | L18: 36849.258 | M18: 37770.49 | N18: 38714.752 | O18: 39682.621
B19: Utilities | E19: {=+_xlfn.ANCHORARRAY(Expenses!F7)} -> 99200 | F19: 101680 | G19: 104222 | H19: 106827.55 | I19: 109498.24 | J19: 112235.69 | K19: 115041.59 | L19: 117917.63 | M19: 120865.57 | N19: 123887.21 | O19: 126984.39
B20: Payroll | E20: {=+_xlfn.ANCHORARRAY(Expenses!F8)} -> 148800 | F20: 152520 | G20: 156333 | H20: 160241.32 | I20: 164247.36 | J20: 168353.54 | K20: 172562.38 | L20: 176876.44 | M20: 181298.35 | N20: 185830.81 | O20: 190476.58
B21: Repair & Maintenance | E21: {=+_xlfn.ANCHORARRAY(Expenses!F9)} -> 86800 | F21: 88970 | G21: 91194.25 | H21: 93474.106 | I21: 95810.959 | J21: 98206.233 | K21: 100661.39 | L21: 103177.92 | M21: 105757.37 | N21: 108401.31 | O21: 111111.34
B22: Management (% of Est. Gross Revenue) | E22: {=+_xlfn.ANCHORARRAY(Expenses!F10)} -> 33028.08 | F22: 37103.516 | G22: 40687.366 | H22: 42073.17 | I22: 43507.095 | J22: 44990.82 | K22: 46526.086 | L22: 48114.692 | M22: 49758.501 | N22: 51459.442 | O22: 53219.509
B23: Insurance | E23: {=+_xlfn.ANCHORARRAY(Expenses!F11)} -> 27900 | F23: 28597.5 | G23: 29312.437 | H23: 30045.248 | I23: 30796.38 | J23: 31566.289 | K23: 32355.446 | L23: 33164.333 | M23: 33993.441 | N23: 34843.277 | O23: 35714.359
B24: Taxes | E24: {=+_xlfn.ANCHORARRAY(Expenses!F12)} -> 167400 | F24: 171585 | G24: 175874.62 | H24: 180271.49 | I24: 184778.28 | J24: 189397.73 | K24: 194132.68 | L24: 198986 | M24: 203960.65 | N24: 209059.66 | O24: 214286.15
B25: Total OpEx | D25: =AVERAGE(_xlfn.ANCHORARRAY(E25))/AVERAGE(_xlfn.ANCHORARRAY(Estimated.Gross.Revenue)) -> 0.48210633 | E25: {=_xlfn.BYCOL(_xlfn.ANCHORARRAY(E17):_xlfn.ANCHORARRAY(E24),_xlfn.LAMBDA(_xlpm.numbers,SUM(_xlpm.numbers)))} -> 625128.08 | F25: 644006.02 | G25: 662762.43 | H25: 679700.11 | I25: 697074.71 | J25: 714897.62 | K25: 733180.56 | L25: 751935.53 | M25: 771174.86 | N25: 790911.21 | O25: 811157.57
B27: Net Operating Income | D27: =AVERAGE(_xlfn.ANCHORARRAY(E27))/AVERAGE(_xlfn.ANCHORARRAY(Estimated.Gross.Revenue)) -> 0.51789367 | E27: {=_xlfn.ANCHORARRAY(Estimated.Gross.Revenue)-_xlfn.ANCHORARRAY(E25)} -> 475807.92 | F27: 592777.86 | G27: 693483.1 | H27: 722738.89 | I27: 753161.78 | J27: 784796.38 | K27: 817688.98 | L27: 851887.54 | M27: 887441.85 | N27: 924403.51 | O27: 962826.06
B29: Capital Expenditures
B30: Re-Leasing Costs | E30: {=SUMIF(_xlfn.ANCHORARRAY(Monthly.Revenue.Year),_xlfn.ANCHORARRAY(E$3),_xlfn.ANCHORARRAY(Forecast.ReLeasing.Cost))} -> 16560 | F30: 16891.2 | G30: 17229.024 | H30: 17573.604 | I30: 17925.077 | J30: 18283.578 | K30: 18649.25 | L30: 19022.235 | M30: 19402.679 | N30: 19790.733 | O30: 20186.548
B31: Value Add Costs | E31: {=Forecast.Value.Add.Costs} -> 350000 | F31: 250000 | G31: 0 | H31: 0 | I31: 0 | J31: 0 | K31: 0 | L31: 0 | M31: 0 | N31: 0 | O31: 0
B32: Misc CapEx | E32: {=SUMIF(_xlfn.ANCHORARRAY(Monthly.Revenue.Year),_xlfn.ANCHORARRAY(E$3),_xlfn.ANCHORARRAY(Forecast.CapEx))} -> 85200 | F32: 88182 | G32: 91268.37 | H32: 94462.763 | I32: 97768.96 | J32: 101190.87 | K32: 104732.55 | L32: 108398.19 | M32: 112192.13 | N32: 116118.85 | O32: 120183.01
B33: Total CapEx | D33: =AVERAGE(_xlfn.ANCHORARRAY(E33))/AVERAGE(_xlfn.ANCHORARRAY(Estimated.Gross.Revenue)) -> 0.30395605 | E33: =SUM(E30:E32) -> 451760 | F33: =SUM(F30:F32) -> 355073.2 | G33: =SUM(G30:G32) -> 108497.39 | H33: =SUM(H30:H32) -> 112036.37 | I33: =SUM(I30:I32) -> 115694.04 | J33: =SUM(J30:J32) -> 119474.45 | K33: =SUM(K30:K32) -> 123381.8 | L33: =SUM(L30:L32) -> 127420.43 | ... O33: =SUM(O30:O32) -> 140369.56
B35: Net Cash Flow From Operations | E35: =E27-E33 -> 24047.92 | F35: =F27-F33 -> 237704.66 | G35: =G27-G33 -> 584985.71 | H35: =H27-H33 -> 610702.52 | I35: =I27-I33 -> 637467.74 | J35: =J27-J33 -> 665321.93 | K35: =K27-K33 -> 694307.17 | L35: =L27-L33 -> 724467.11 | ... O35: =O27-O33 -> 822456.5

Sheet Debt
B2: Permanent Financing
B4: =Property -> Flashewoode Heights | D4: Initial | E4: {=_xlfn.ANCHORARRAY(Timeline)} -> 1 | F4: 2 | G4: 3 | H4: 4 | I4: 5 | J4: 6 | K4: 7 | L4: 8 | M4: 9 | N4: 10 | O4: 11
C5: Debt Service | E5: =IF(OR(E4<=PIK.Period,E4>Term),0,PPMT(Interest.Rate,E4,Amort.Period-PIK.Period,Loan.Amount)) -> 0 | F5: =IF(OR(F4<=PIK.Period,F4>Term),0,PPMT(Interest.Rate,F4,Amort.Period-PIK.Period,Loan.Amount)) -> 0 | G5: =IF(OR(G4<=PIK.Period,G4>Term),0,PPMT(Interest.Rate,G4,Amort.Period-PIK.Period,Loan.Amount)) -> -78561.714 | H5: =IF(OR(H4<=PIK.Period,H4>Term),0,PPMT(Interest.Rate,H4,Amort.Period-PIK.Period,Loan.Amount)) -> -84061.034 | I5: =IF(OR(I4<=PIK.Period,I4>Term),0,PPMT(Interest.Rate,I4,Amort.Period-PIK.Period,Loan.Amount)) -> -89945.307 | J5: =IF(OR(J4<=PIK.Period,J4>Term),0,PPMT(Interest.Rate,J4,Amort.Period-PIK.Period,Loan.Amount)) -> -96241.478 | K5: =IF(OR(K4<=PIK.Period,K4>Term),0,PPMT(Interest.Rate,K4,Amort.Period-PIK.Period,Loan.Amount)) -> -102978.38 | L5: =IF(OR(L4<=PIK.Period,L4>Term),0,PPMT(Interest.Rate,L4,Amort.Period-PIK.Period,Loan.Amount)) -> -110186.87 | ... O5: =IF(OR(O4<=PIK.Period,O4>Term),0,PPMT(Interest.Rate,O4,Amort.Period-PIK.Period,Loan.Amount)) -> -134983.65
C6: Interest Expense | E6: =IPMT(Interest.Rate,E4,Amort.Period,Loan.Amount) -> -329875 | F6: =IPMT(Interest.Rate,F4,Amort.Period,Loan.Amount) -> -325787.21 | G6: =IPMT(Interest.Rate,G4,Amort.Period,Loan.Amount) -> -321413.28 | H6: =IPMT(Interest.Rate,H4,Amort.Period,Loan.Amount) -> -316733.17 | I6: =IPMT(Interest.Rate,I4,Amort.Period,Loan.Amount) -> -311725.46 | J6: =IPMT(Interest.Rate,J4,Amort.Period,Loan.Amount) -> -306367.2 | K6: =IPMT(Interest.Rate,K4,Amort.Period,Loan.Amount) -> -300633.87 | L6: =IPMT(Interest.Rate,L4,Amort.Period,Loan.Amount) -> -294499.2 | ... O6: =IPMT(Interest.Rate,O4,Amort.Period,Loan.Amount) -> -273396.3
C7: Loan Balance | D7: =Loan.Amount -> 4712500 | E7: =+D7+E5 -> 4712500 | F7: =+E7+F5 -> 4712500 | G7: =+F7+G5 -> 4633938.3 | H7: =+G7+H5 -> 4549877.3 | I7: =+H7+I5 -> 4459931.9 | J7: =+I7+J5 -> 4363690.5 | K7: =+J7+K5 -> 4260712.1 | L7: =+K7+L5 -> 4150525.2 | ... O7: =+N7+O5 -> 3771488.7

Sheet Calc Modules-->

Sheet Forecast. Monthly Rent
B2: Multifamily Rent Forecast
E3: {=TRANSPOSE(rent.roll.assumptions)} -> Unit Name | F3: Studio | G3: 1bd/1ba | H3: 2bd/2ba | I3: 2bd/1.5ba | J3: 3bd/2ba
E4: # of Units | F4: 40 | G4: 24 | H4: 24 | I4: 12 | J4: 24
E5: Bedrooms | F5: 0 | G5: 1 | H5: 2 | I5: 2 | J5: 3
E6: Baths | F6: 1 | G6: 1 | H6: 2 | I6: 1.5 | J6: 2
E7: Rentable Area | F7: 430 | G7: 671 | H7: 945 | I7: 1025 | J7: 1046
E8: In-Place Rent/Mo | F8: 510 | G8: 660 | H8: 850 | I8: 850 | J8: 1100
E9: Market Rent/Mo | F9: 630 | G9: 780 | H9: 970 | I9: 970 | J9: 1220
E10: Months to roll to market | F10: 12 | G10: 16 | H10: 19 | I10: 22 | J10: 25
E11: Lease Term | F11: 12 | G11: 12 | H11: 12 | I11: 12 | J11: 12
E12: CapEx/Unit | F12: 50 | G12: 50 | H12: 60 | I12: 65 | J12: 70
E13: Free Rent Per New Lease | F13: 1 | G13: 1 | H13: 0 | I13: 0 | J13: 0
E14: Vacancy Between Leases | F14: 20 | G14: 20 | H14: 25 | I14: 25 | J14: 30
E15: Re-Leasing Costs | F15: 300 | G15: 300 | H15: 350 | I15: 350 | J15: 400
... E18: Blended Releasing Cost | F18: 120 | G18: 120 | H18: 140 | I18: 140 | J18: 160
B20: Rent Forecast
B21: Month | C21: Year | D21: Date | E21: Total | F21: {=+F3:J3} -> Studio | G21: 1bd/1ba | H21: 2bd/2ba | I21: 2bd/1.5ba | J21: 3bd/2ba
B22: {=_xlfn.SEQUENCE(12*Term.Cap.Year,1,1)} -> 1 | C22: {=ROUNDUP(_xlfn.ANCHORARRAY(B22)/12,0)} -> 1 | D22: {=EOMONTH(Start.Date,_xlfn.ANCHORARRAY(B22)-1)} -> 45838 | E22: {=_xlfn.BYROW(_xlfn.ANCHORARRAY(F22),_xlfn.LAMBDA(_xlpm.array,SUM(_xlpm.array)))} -> 93240 | F22: {=IF(_xlfn.ANCHORARRAY($B$22)<F$10:J$10,F$8:J$8,F$9:J$9)*F$4:J$4*(1+Infl.Rent)^(_xlfn.ANCHORARRAY($C$22)-1)} -> 20400 | G22: 15840 | H22: 20400 | I22: 10200 | J22: 26400
B23: 2 | C23: 1 | D23: 45869 | E23: 93240 | F23: 20400 | G23: 15840 | H23: 20400 | I23: 10200 | J23: 26400
B24: 3 | C24: 1 | D24: 45900 | E24: 93240 | F24: 20400 | G24: 15840 | H24: 20400 | I24: 10200 | J24: 26400
B25: 4 | C25: 1 | D25: 45930 | E25: 93240 | F25: 20400 | G25: 15840 | H25: 20400 | I25: 10200 | J25: 26400
B26: 5 | C26: 1 | D26: 45961 | E26: 93240 | F26: 20400 | G26: 15840 | H26: 20400 | I26: 10200 | J26: 26400
B27: 6 | C27: 1 | D27: 45991 | E27: 93240 | F27: 20400 | G27: 15840 | H27: 20400 | I27: 10200 | J27: 26400
B28: 7 | C28: 1 | D28: 46022 | E28: 93240 | F28: 20400 | G28: 15840 | H28: 20400 | I28: 10200 | J28: 26400
B29: 8 | C29: 1 | D29: 46053 | E29: 93240 | F29: 20400 | G29: 15840 | H29: 20400 | I29: 10200 | J29: 26400
B30: 9 | C30: 1 | D30: 46081 | E30: 93240 | F30: 20400 | G30: 15840 | H30: 20400 | I30: 10200 | J30: 26400
B31: 10 | C31: 1 | D31: 46112 | E31: 93240 | F31: 20400 | G31: 15840 | H31: 20400 | I31: 10200 | J31: 26400
B32: 11 | C32: 1 | D32: 46142 | E32: 93240 | F32: 20400 | G32: 15840 | H32: 20400 | I32: 10200 | J32: 26400
B33: 12 | C33: 1 | D33: 46173 | E33: 98040 | F33: 25200 | G33: 15840 | H33: 20400 | I33: 10200 | J33: 26400
B34: 13 | C34: 2 | D34: 46203 | E34: 101471.4 | F34: 26082 | G34: 16394.4 | H34: 21114 | I34: 10557 | J34: 27324
... B153: 132 | C153: 11 | D153: 49826 | E153: 152513.94 | F153: 35547.089 | G153: 26406.409 | H153: 32838.739 | I153: 16419.37 | J153: 41302.332

Sheet Forecast.Free Rent
B2: Multifamily Rent Forecast
E3: {=TRANSPOSE(rent.roll.assumptions)} -> Unit Name | F3: Studio | G3: 1bd/1ba | H3: 2bd/2ba | I3: 2bd/1.5ba | J3: 3bd/2ba
E4: # of Units | F4: 40 | G4: 24 | H4: 24 | I4: 12 | J4: 24
E5: Bedrooms | F5: 0 | G5: 1 | H5: 2 | I5: 2 | J5: 3
E6: Baths | F6: 1 | G6: 1 | H6: 2 | I6: 1.5 | J6: 2
E7: Rentable Area | F7: 430 | G7: 671 | H7: 945 | I7: 1025 | J7: 1046
E8: In-Place Rent/Mo | F8: 510 | G8: 660 | H8: 850 | I8: 850 | J8: 1100
E9: Market Rent/Mo | F9: 630 | G9: 780 | H9: 970 | I9: 970 | J9: 1220
E10: Months to roll to market | F10: 12 | G10: 16 | H10: 19 | I10: 22 | J10: 25
E11: Lease Term | F11: 12 | G11: 12 | H11: 12 | I11: 12 | J11: 12
E12: CapEx/Unit | F12: 50 | G12: 50 | H12: 60 | I12: 65 | J12: 70
E13: Free Rent Per New Lease | F13: 1 | G13: 1 | H13: 0 | I13: 0 | J13: 0
E14: Vacancy Between Leases | F14: 20 | G14: 20 | H14: 25 | I14: 25 | J14: 30
E15: Re-Leasing Costs | F15: 300 | G15: 300 | H15: 350 | I15: 350 | J15: 400
... E18: Blended Releasing Cost | F18: 120 | G18: 120 | H18: 140 | I18: 140 | J18: 160
B20: Free Rent Forecast
B21: Month | C21: Year | D21: Date | E21: Total | F21: {=+F3:J3} -> Studio | G21: 1bd/1ba | H21: 2bd/2ba | I21: 2bd/1.5ba | J21: 3bd/2ba
B22: {=_xlfn.SEQUENCE(12*Term.Cap.Year,1,1)} -> 1 | C22: {=ROUNDUP(_xlfn.ANCHORARRAY(B22)/12,0)} -> 1 | D22: {=EOMONTH(Start.Date,_xlfn.ANCHORARRAY(B22)-1)} -> 45838 | E22: {=_xlfn.BYROW(_xlfn.ANCHORARRAY(F22),_xlfn.LAMBDA(_xlpm.array,SUM(_xlpm.array)))} -> 0 | F22: {=IF(_xlfn.ANCHORARRAY(B22)/12=INT(_xlfn.ANCHORARRAY(B22)/12),1,0)*_xlfn.ANCHORARRAY(Monthly.Forecast.Unit)*F13:J13} -> 0 | G22: 0 | H22: 0 | I22: 0 | J22: 0
B23: 2 | C23: 1 | D23: 45869 | E23: 0 | F23: 0 | G23: 0 | H23: 0 | I23: 0 | J23: 0
B24: 3 | C24: 1 | D24: 45900 | E24: 0 | F24: 0 | G24: 0 | H24: 0 | I24: 0 | J24: 0
B25: 4 | C25: 1 | D25: 45930 | E25: 0 | F25: 0 | G25: 0 | H25: 0 | I25: 0 | J25: 0
B26: 5 | C26: 1 | D26: 45961 | E26: 0 | F26: 0 | G26: 0 | H26: 0 | I26: 0 | J26: 0
B27: 6 | C27: 1 | D27: 45991 | E27: 0 | F27: 0 | G27: 0 | H27: 0 | I27: 0 | J27: 0
B28: 7 | C28: 1 | D28: 46022 | E28: 0 | F28: 0 | G28: 0 | H28: 0 | I28: 0 | J28: 0
B29: 8 | C29: 1 | D29: 46053 | E29: 0 | F29: 0 | G29: 0 | H29: 0 | I29: 0 | J29: 0
B30: 9 | C30: 1 | D30: 46081 | E30: 0 | F30: 0 | G30: 0 | H30: 0 | I30: 0 | J30: 0
B31: 10 | C31: 1 | D31: 46112 | E31: 0 | F31: 0 | G31: 0 | H31: 0 | I31: 0 | J31: 0
B32: 11 | C32: 1 | D32: 46142 | E32: 0 | F32: 0 | G32: 0 | H32: 0 | I32: 0 | J32: 0
B33: 12 | C33: 1 | D33: 46173 | E33: 41040 | F33: 25200 | G33: 15840 | H33: 0 | I33: 0 | J33: 0
B34: 13 | C34: 2 | D34: 46203 | E34: 0 | F34: 0 | G34: 0 | H34: 0 | I34: 0 | J34: 0
... B153: 132 | C153: 11 | D153: 49826 | E153: 61953.498 | F153: 35547.089 | G153: 26406.409 | H153: 0 | I153: 0 | J153: 0

Sheet Forecast.CAPEX
B2: Multifamily Rent Forecast
E3: {=TRANSPOSE(rent.roll.assumptions)} -> Unit Name | F3: Studio | G3: 1bd/1ba | H3: 2bd/2ba | I3: 2bd/1.5ba | J3: 3bd/2ba
E4: # of Units | F4: 40 | G4: 24 | H4: 24 | I4: 12 | J4: 24
E5: Bedrooms | F5: 0 | G5: 1 | H5: 2 | I5: 2 | J5: 3
E6: Baths | F6: 1 | G6: 1 | H6: 2 | I6: 1.5 | J6: 2
E7: Rentable Area | F7: 430 | G7: 671 | H7: 945 | I7: 1025 | J7: 1046
E8: In-Place Rent/Mo | F8: 510 | G8: 660 | H8: 850 | I8: 850 | J8: 1100
E9: Market Rent/Mo | F9: 630 | G9: 780 | H9: 970 | I9: 970 | J9: 1220
E10: Months to roll to market | F10: 12 | G10: 16 | H10: 19 | I10: 22 | J10: 25
E11: Lease Term | F11: 12 | G11: 12 | H11: 12 | I11: 12 | J11: 12
E12: CapEx/Unit | F12: 50 | G12: 50 | H12: 60 | I12: 65 | J12: 70
E13: Free Rent Per New Lease | F13: 1 | G13: 1 | H13: 0 | I13: 0 | J13: 0
E14: Vacancy Between Leases | F14: 20 | G14: 20 | H14: 25 | I14: 25 | J14: 30
E15: Re-Leasing Costs | F15: 300 | G15: 300 | H15: 350 | I15: 350 | J15: 400
... E18: Blended Releasing Cost | F18: 120 | G18: 120 | H18: 140 | I18: 140 | J18: 160
B20: CAPEX Forecast
B21: Month | C21: Year | D21: Date | E21: Total | F21: {=+F3:J3} -> Studio | G21: 1bd/1ba | H21: 2bd/2ba | I21: 2bd/1.5ba | J21: 3bd/2ba
B22: {=_xlfn.SEQUENCE(12*Term.Cap.Year,1,1)} -> 1 | C22: {=ROUNDUP(_xlfn.ANCHORARRAY(B22)/12,0)} -> 1 | D22: {=EOMONTH(Start.Date,_xlfn.ANCHORARRAY(B22)-1)} -> 45838 | E22: {=_xlfn.BYROW(_xlfn.ANCHORARRAY(F22),_xlfn.LAMBDA(_xlpm.array,SUM(_xlpm.array)))} -> 7100 | F22: {=F4:J4*F12:J12*(1+Infl.CapEx)^(_xlfn.ANCHORARRAY(C22)-1)} -> 2000 | G22: 1200 | H22: 1440 | I22: 780 | J22: 1680
B23: 2 | C23: 1 | D23: 45869 | E23: 7100 | F23: 2000 | G23: 1200 | H23: 1440 | I23: 780 | J23: 1680
B24: 3 | C24: 1 | D24: 45900 | E24: 7100 | F24: 2000 | G24: 1200 | H24: 1440 | I24: 780 | J24: 1680
B25: 4 | C25: 1 | D25: 45930 | E25: 7100 | F25: 2000 | G25: 1200 | H25: 1440 | I25: 780 | J25: 1680
B26: 5 | C26: 1 | D26: 45961 | E26: 7100 | F26: 2000 | G26: 1200 | H26: 1440 | I26: 780 | J26: 1680
B27: 6 | C27: 1 | D27: 45991 | E27: 7100 | F27: 2000 | G27: 1200 | H27: 1440 | I27: 780 | J27: 1680
B28: 7 | C28: 1 | D28: 46022 | E28: 7100 | F28: 2000 | G28: 1200 | H28: 1440 | I28: 780 | J28: 1680
B29: 8 | C29: 1 | D29: 46053 | E29: 7100 | F29: 2000 | G29: 1200 | H29: 1440 | I29: 780 | J29: 1680
B30: 9 | C30: 1 | D30: 46081 | E30: 7100 | F30: 2000 | G30: 1200 | H30: 1440 | I30: 780 | J30: 1680
B31: 10 | C31: 1 | D31: 46112 | E31: 7100 | F31: 2000 | G31: 1200 | H31: 1440 | I31: 780 | J31: 1680
B32: 11 | C32: 1 | D32: 46142 | E32: 7100 | F32: 2000 | G32: 1200 | H32: 1440 | I32: 780 | J32: 1680
B33: 12 | C33: 1 | D33: 46173 | E33: 7100 | F33: 2000 | G33: 1200 | H33: 1440 | I33: 780 | J33: 1680
B34: 13 | C34: 2 | D34: 46203 | E34: 7348.5 | F34: 2070 | G34: 1242 | H34: 1490.4 | I34: 807.3 | J34: 1738.8
... B153: 132 | C153: 11 | D153: 49826 | E153: 10015.251 | F153: 2821.1975 | G153: 1692.7185 | H153: 2031.2622 | I153: 1100.267 | J153: 2369.8059

Sheet Forecast.Vacancy
B2: Multifamily Rent Forecast
E3: {=TRANSPOSE(rent.roll.assumptions)} -> Unit Name | F3: Studio | G3: 1bd/1ba | H3: 2bd/2ba | I3: 2bd/1.5ba | J3: 3bd/2ba
E4: # of Units | F4: 40 | G4: 24 | H4: 24 | I4: 12 | J4: 24
E5: Bedrooms | F5: 0 | G5: 1 | H5: 2 | I5: 2 | J5: 3
E6: Baths | F6: 1 | G6: 1 | H6: 2 | I6: 1.5 | J6: 2
E7: Rentable Area | F7: 430 | G7: 671 | H7: 945 | I7: 1025 | J7: 1046
E8: In-Place Rent/Mo | F8: 510 | G8: 660 | H8: 850 | I8: 850 | J8: 1100
E9: Market Rent/Mo | F9: 630 | G9: 780 | H9: 970 | I9: 970 | J9: 1220
E10: Months to roll to market | F10: 12 | G10: 16 | H10: 19 | I10: 22 | J10: 25
E11: Lease Term | F11: 12 | G11: 12 | H11: 12 | I11: 12 | J11: 12
E12: CapEx/Unit | F12: 50 | G12: 50 | H12: 60 | I12: 65 | J12: 70
E13: Free Rent Per New Lease | F13: 1 | G13: 1 | H13: 0 | I13: 0 | J13: 0
E14: Vacancy Between Leases | F14: 20 | G14: 20 | H14: 25 | I14: 25 | J14: 30
E15: Re-Leasing Costs | F15: 300 | G15: 300 | H15: 350 | I15: 350 | J15: 400
... E18: Blended Releasing Cost | F18: 120 | G18: 120 | H18: 140 | I18: 140 | J18: 160
B20: Vacancy Forecast
B21: Month | C21: Year | D21: Date | E21: Total | F21: {=+F3:J3} -> Studio | G21: 1bd/1ba | H21: 2bd/2ba | I21: 2bd/1.5ba | J21: 3bd/2ba
B22: {=_xlfn.SEQUENCE(12*Term.Cap.Year,1,1)} -> 1 | C22: {=ROUNDUP(_xlfn.ANCHORARRAY(B22)/12,0)} -> 1 | D22: {=EOMONTH(Start.Date,_xlfn.ANCHORARRAY(B22)-1)} -> 45838 | E22: {=_xlfn.BYROW(_xlfn.ANCHORARRAY(F22),_xlfn.LAMBDA(_xlpm.array,SUM(_xlpm.array)))} -> 0 | F22: {=IF(_xlfn.ANCHORARRAY(B22)/12=INT(_xlfn.ANCHORARRAY(B22)/12),1,0)*_xlfn.ANCHORARRAY(Monthly.Forecast.Unit)*F17:J17/30} -> 0 | G22: 0 | H22: 0 | I22: 0 | J22: 0
B23: 2 | C23: 1 | D23: 45869 | E23: 0 | F23: 0 | G23: 0 | H23: 0 | I23: 0 | J23: 0
B24: 3 | C24: 1 | D24: 45900 | E24: 0 | F24: 0 | G24: 0 | H24: 0 | I24: 0 | J24: 0
B25: 4 | C25: 1 | D25: 45930 | E25: 0 | F25: 0 | G25: 0 | H25: 0 | I25: 0 | J25: 0
B26: 5 | C26: 1 | D26: 45961 | E26: 0 | F26: 0 | G26: 0 | H26: 0 | I26: 0 | J26: 0
B27: 6 | C27: 1 | D27: 45991 | E27: 0 | F27: 0 | G27: 0 | H27: 0 | I27: 0 | J27: 0
B28: 7 | C28: 1 | D28: 46022 | E28: 0 | F28: 0 | G28: 0 | H28: 0 | I28: 0 | J28: 0
B29: 8 | C29: 1 | D29: 46053 | E29: 0 | F29: 0 | G29: 0 | H29: 0 | I29: 0 | J29: 0
B30: 9 | C30: 1 | D30: 46081 | E30: 0 | F30: 0 | G30: 0 | H30: 0 | I30: 0 | J30: 0
B31: 10 | C31: 1 | D31: 46112 | E31: 0 | F31: 0 | G31: 0 | H31: 0 | I31: 0 | J31: 0
B32: 11 | C32: 1 | D32: 46142 | E32: 0 | F32: 0 | G32: 0 | H32: 0 | I32: 0 | J32: 0
B33: 12 | C33: 1 | D33: 46173 | E33: 31704 | F33: 6720 | G33: 4224 | H33: 6800 | I33: 3400 | J33: 10560
B34: 13 | C34: 2 | D34: 46203 | E34: 0 | F34: 0 | G34: 0 | H34: 0 | I34: 0 | J34: 0
... B153: 132 | C153: 11 | D153: 49826 | E153: 49461.235 | F153: 9479.2237 | G153: 7041.709 | H153: 10946.246 | I153: 5473.1232 | J153: 16520.933

Sheet Forecast.ReLeasing
B2: Multifamily Rent Forecast
E3: {=TRANSPOSE(rent.roll.assumptions)} -> Unit Name | F3: Studio | G3: 1bd/1ba | H3: 2bd/2ba | I3: 2bd/1.5ba | J3: 3bd/2ba
E4: # of Units | F4: 40 | G4: 24 | H4: 24 | I4: 12 | J4: 24
E5: Bedrooms | F5: 0 | G5: 1 | H5: 2 | I5: 2 | J5: 3
E6: Baths | F6: 1 | G6: 1 | H6: 2 | I6: 1.5 | J6: 2
E7: Rentable Area | F7: 430 | G7: 671 | H7: 945 | I7: 1025 | J7: 1046
E8: In-Place Rent/Mo | F8: 510 | G8: 660 | H8: 850 | I8: 850 | J8: 1100
E9: Market Rent/Mo | F9: 630 | G9: 780 | H9: 970 | I9: 970 | J9: 1220
E10: Months to roll to market | F10: 12 | G10: 16 | H10: 19 | I10: 22 | J10: 25
E11: Lease Term | F11: 12 | G11: 12 | H11: 12 | I11: 12 | J11: 12
E12: CapEx/Unit | F12: 50 | G12: 50 | H12: 60 | I12: 65 | J12: 70
E13: Free Rent Per New Lease | F13: 1 | G13: 1 | H13: 0 | I13: 0 | J13: 0
E14: Vacancy Between Leases | F14: 20 | G14: 20 | H14: 25 | I14: 25 | J14: 30
E15: Re-Leasing Costs | F15: 300 | G15: 300 | H15: 350 | I15: 350 | J15: 400
... E18: Blended Releasing Cost | F18: 120 | G18: 120 | H18: 140 | I18: 140 | J18: 160
B20: ReLeasing Forecast
B21: Month | C21: Year | D21: Date | E21: Total | F21: {=+F3:J3} -> Studio | G21: 1bd/1ba | H21: 2bd/2ba | I21: 2bd/1.5ba | J21: 3bd/2ba
B22: {=_xlfn.SEQUENCE(12*Term.Cap.Year,1,1)} -> 1 | C22: {=ROUNDUP(_xlfn.ANCHORARRAY(B22)/12,0)} -> 1 | D22: {=EOMONTH(Start.Date,_xlfn.ANCHORARRAY(B22)-1)} -> 45838 | E22: {=_xlfn.BYROW(_xlfn.ANCHORARRAY(F22),_xlfn.LAMBDA(_xlpm.array,SUM(_xlpm.array)))} -> 0 | F22: {=IF(_xlfn.ANCHORARRAY(B22)/12=INT(_xlfn.ANCHORARRAY(B22)/12),1,0)*F4:J4*F18:J18*(1+Infl.ReLeasing.Costs)^(_xlfn.ANCHORARRAY(C22)-1)} -> 0 | G22: 0 | H22: 0 | I22: 0 | J22: 0
B23: 2 | C23: 1 | D23: 45869 | E23: 0 | F23: 0 | G23: 0 | H23: 0 | I23: 0 | J23: 0
B24: 3 | C24: 1 | D24: 45900 | E24: 0 | F24: 0 | G24: 0 | H24: 0 | I24: 0 | J24: 0
B25: 4 | C25: 1 | D25: 45930 | E25: 0 | F25: 0 | G25: 0 | H25: 0 | I25: 0 | J25: 0
B26: 5 | C26: 1 | D26: 45961 | E26: 0 | F26: 0 | G26: 0 | H26: 0 | I26: 0 | J26: 0
B27: 6 | C27: 1 | D27: 45991 | E27: 0 | F27: 0 | G27: 0 | H27: 0 | I27: 0 | J27: 0
B28: 7 | C28: 1 | D28: 46022 | E28: 0 | F28: 0 | G28: 0 | H28: 0 | I28: 0 | J28: 0
B29: 8 | C29: 1 | D29: 46053 | E29: 0 | F29: 0 | G29: 0 | H29: 0 | I29: 0 | J29: 0
B30: 9 | C30: 1 | D30: 46081 | E30: 0 | F30: 0 | G30: 0 | H30: 0 | I30: 0 | J30: 0
B31: 10 | C31: 1 | D31: 46112 | E31: 0 | F31: 0 | G31: 0 | H31: 0 | I31: 0 | J31: 0
B32: 11 | C32: 1 | D32: 46142 | E32: 0 | F32: 0 | G32: 0 | H32: 0 | I32: 0 | J32: 0
B33: 12 | C33: 1 | D33: 46173 | E33: 16560 | F33: 4800 | G33: 2880 | H33: 3360 | I33: 1680 | J33: 3840
B34: 13 | C34: 2 | D34: 46203 | E34: 0 | F34: 0 | G34: 0 | H34: 0 | I34: 0 | J34: 0
... B153: 132 | C153: 11 | D153: 49826 | E153: 20186.548 | F153: 5851.1732 | G153: 3510.7039 | H153: 4095.8213 | I153: 2047.9106 | J153: 4680.9386
